Workbook

Sheet Summary
A1: 2 Channel Dual Voltage-Current Meter: firmware v1.0.0 release report
A2: First production release. Compared against v0.3.0. Updated 27 Sep 2026 for the final release file (voltage calibration line).
A4: Release
A5: Firmware file | B5: 2_channel_dual_voltage_current_meter_fw_v1.0.0.ino (final)
A6: Target | B6: Arduino Nano (ATmega328P), Arduino AVR core
A7: Tested binary | B7: The final release file compiles to exactly the build every test suite ran on (production and debug)
A8: Voltage calibration | B8: displayed = measured x 0.99578 + 31 mV, rounded to 10 mV: 0.790-20.110 V, then OL
A9: Verdict | B9: Ready for release: no failures in any simulated test; bench voltage check agrees with a Fluke 15B+
A10: Release condition | B10: Release after the remaining Bench Test Plan checks pass
A12: Simulated tests (v1.0.0)
A13: Test cases | B13: =COUNTA('Test Cases'!A5:A105) -> 101
A14: Passed | B14: =COUNTIF('Test Cases'!H5:H105,"PASS") -> 98
A15: Failed | B15: =COUNTIF('Test Cases'!H5:H105,"FAIL") -> 0
A16: Observations | B16: =COUNTIF('Test Cases'!H5:H105,"OBSERVATION") -> 3 | D16: Behavior kept from v0.3.0 on purpose; see Findings.
A18: Unit tests (functions called directly on the chip)
A19: Unit test cases | B19: ='Unit Tests'!C14 -> 234322
A20: Mismatches against the models | B20: ='Unit Tests'!D14 -> 0 | D20: Must be 0.
A22: Parity with v0.3.0 (every ADC code 0-1023)
A23: Voltage: identical | B23: =COUNTIF('ADC Parity'!F5:F1028,"Identical") -> 595
A24: Voltage: within 10 mV (calibration line) | B24: =COUNTIF('ADC Parity'!F5:F1028,"Within 10 mV (calibration line)") -> 423 | D24: The line replaces the 7 offset bands; mean difference 0.0 mV.
A25: Voltage: -20 mV at the end of the old +30 mV band | B25: =COUNTIF('ADC Parity'!F5:F1028,"-20 mV (end of old +30 mV band)") -> 3 | D25: 4.13-4.17 V: the old band over-corrected there.
A26: Voltage: low range fixed (0.82, 0.84 V) | B26: =COUNTIF('ADC Parity'!F5:F1028,"Low range fixed (F-02)") -> 2 | D26: v0.3.0 showed 0.790 / 0.800 here and ran backwards.
A27: Voltage: ADC full scale now OL | B27: =COUNTIF('ADC Parity'!F5:F1028,"ADC full scale: now OL") -> 1
A28: Current: identical | B28: =COUNTIF('ADC Parity'!J5:J1028,"Identical") -> 852
A29: Current: +0.01 A (nearest step) | B29: =COUNTIF('ADC Parity'!J5:J1028,"+0.01 A (nearest step)") -> 58 | D29: v1.0.0 picks the closer table value; v0.3.0 leaned to the lower one.
A30: Current: gap bug fixed (2.49/2.50 A) | B30: =COUNTIF('ADC Parity'!J5:J1028,"Gap bug fixed") -> 2
A31: Current: above 5.00 A now OL | B31: =COUNTIF('ADC Parity'!J5:J1028,"Above 5.00 A: now OL") -> 112
A32: Unexplained differences | B32: =COUNTIF('ADC Parity'!F5:F1028,"Different")+COUNTIF('ADC Parity'!J5:J1028,"Different") -> 0 | D32: Must be 0.
A34: Findings
A35: Open: check on bench | B35: =COUNTIF(Findings!C5:C18,"Open - check on bench") -> 4
A36: Open: recommendations | B36: =COUNTIF(Findings!C5:C18,"Open - recommendation") -> 8
A37: Fixed in the final file | B37: =COUNTIF(Findings!C5:C18,"Fixed in final file") -> 2 | D37: F-02 and F-03: removed by the calibration line.
A39: Stability (display changes in 1,500 noisy cycles)
A40: v0.3.0 | B40: ='Stability Tests'!D10 -> 528
A41: v1.0.0 | B41: ='Stability Tests'!F10 -> 4
A42: Reduction | B42: ='Stability Tests'!H10 -> 0.99242424
A44: Voltage accuracy
A45: Estimated spec | B45: ±(0.1 % + 2 digits) | D45: Error budget on the Voltage Accuracy sheet; 1 digit = 10 mV.
A46: Fluke 15B+ points inside its tolerance | B46: ='Voltage Accuracy'!B21 -> 10 of 10
A47: Largest difference where the Fluke can decide (mV) | B47: ='Voltage Accuracy'!B23 -> #VALUE! | D47: Below 4 V; above 4 V a better reference is needed (F-13, BT-49).
...

Sheet Changes
A1: Modifications from v0.3.0 to v1.0.0
A2: v0.3.0 = 2_channel_dual_voltage_current_meter_fw_v0.3.0.ino. v1.0.0 = 2_channel_dual_voltage_current_meter_fw_v1.0.0.ino.
A4: ID | B4: Area | C4: Type | D4: v0.3.0 behavior | E4: v1.0.0 behavior | F4: User visible | G4: Verified by
A5: CH-01 | B5: Current | C5: Bug fix | D5: Linear search in two halves; 2.219-2.228 V (2.49-2.50 A) fell in neither half | E5: Binary search over the whole table | F5: Yes | G5: C-03
A6: CH-02 | B6: Current | C6: Behavior change | D6: Picks the lower step unless the reading is > 5 mV above it | E6: Picks the truly nearest step (58 of 912 codes show +0.01 A) | F6: Yes | G6: C-02, C-05
A7: CH-03 | B7: Current | C7: Bug fix | D7: Above 5.00 A returns 999.23: display "999.2A0", LED off | E7: "OL" in the current field, LED on | F7: Yes | G7: C-04, L-03
A8: CH-04 | B8: Voltage | C8: Enhancement | D8: ADC full scale shows 20.130 V | E8: "OL" in the voltage field | F8: Yes | G8: V-02
A9: CH-05 | B9: ADC | C9: Enhancement | D9: 1 sample per reading | E9: 64 samples per channel (16 for temperature), fractional average | F9: Yes (stability) | G9: V-06 to V-08, C-07, C-08
A10: CH-06 | B10: ADC | C10: Enhancement | D10: None | E10: Outlier rejection: samples > 8 counts from the median are ignored | F10: Yes (dropouts) | G10: A-07 to A-09
A11: CH-07 | B11: ADC | C11: Enhancement | D11: 1 settling read after a channel switch | E11: 2 settling reads | F11: No | G11: A-03, A-06
A12: CH-08 | B12: ADC | C12: Enhancement | D12: Fixed sample timing | E12: 0-7 us random jitter between samples | F12: No | G12: A-04
A13: CH-09 | B13: Display | C13: Enhancement | D13: None | E13: Hysteresis: 3 mV on voltage steps, 1.5 mV on current steps | F13: Yes (no flicker) | G13: V-07, V-09, C-07
A14: CH-10 | B14: Display | C14: Enhancement | D14: n/a | E14: Hysteresis cleared at startup, over range, below 0.790 V and on alert changes | F14: No | G14: T-05
A15: CH-11 | B15: Temperature | C15: Enhancement | D15: Alert on and off at 0.680 V (toggles near threshold) | E15: On at 0.680 V, off below 0.670 V | F15: Yes | G15: T-02, T-03
... A28: CH-24 | B28: Voltage | C28: Calibration | D28: 7 offset bands (+30 to -40 mV) added after truncating to 10 mV; special low range (0.790 / 0.810 V below 0.800 V) | E28: One calibration line: displayed = measured x 0.99578 + 31 mV (fit of the same bands), rounded to the nearest 10 mV; 0.000 below 0.790 V. Constants VOLTAGE_CAL_GAIN / VOLTAGE_CAL_OFFSET_MV (1.0 / 0.0 = no compensation). 410 B less flash. | F28: Yes (within 10 mV; no backwards steps) | G28: V-01, V-04, V-05, V-09, V-11, V-12

Sheet Enhancements
A1: What v1.0.0 improves, with measured evidence
A2: All figures are measured in the simulation runs (see Method). Improvement columns are formulas.
A4: Enhancement | B4: Metric | C4: v0.3.0 | D4: v1.0.0 | E4: Improvement | F4: Evidence
A5: Stable voltage display | B5: Display changes, 10 mV boundary (ADC 611.40), 300 cycles | C5: 158 | D5: 3 | E5: =IF(C5=0,0,1-D5/C5) -> 0.98101266 | F5: V-07
A6: Stable voltage display | B6: Display changes inside a step (ADC 611.15), 300 cycles | C6: 188 | D6: 0 | E6: =IF(C6=0,0,1-D6/C6) -> 1 | F6: V-08
A7: Stable current display | B7: Display changes, 0.01 A boundary, 300 cycles | C7: 142 | D7: 1 | E7: =IF(C7=0,0,1-D7/C7) -> 0.99295775 | F7: C-07
A8: Stable current display | B8: Display changes inside a step, 300 cycles | C8: 30 | D8: 0 | E8: =IF(C8=0,0,1-D8/C8) -> 1 | F8: C-08
A9: Dropout immunity | B9: Cycles showing 0.02 A with 2% dropouts, of 300 | C9: 5 | D9: 0 | E9: =IF(C9=0,0,1-D9/C9) -> 1 | F9: A-07
A10: Voltage resolution | B10: Distinct displayed voltages reachable | C10: 984 | D10: 1934 | E10: =IF(C10=0,0,D10/C10) -> 1.9654472 | F10: V-06, V-11; fine sweep
A11: Correct current in 2.49-2.50 A | B11: ADC codes showing an error value | C11: 2 | D11: 0 | E11: =IF(C11=0,0,1-D11/C11) -> 1 | F11: C-03
A12: Clear over-range display | B12: Codes showing garbage "999.2A0" | C12: 112 | D12: 0 | E12: =IF(C12=0,0,1-D12/C12) -> 1 | F12: C-04
A13: Clean LCD rows | B13: Sweep steps with a leftover character | C13: 569 | D13: 0 | E13: =IF(C13=0,0,1-D13/C13) -> 1 | F13: D-01
A14: No alert flicker | B14: Screen clears per alert cycle | C14: 1 | D14: 0 | E14: =IF(C14=0,0,1-D14/C14) -> 1 | F14: D-05
A15: Alert hysteresis | B15: Alert state changes while hovering 0.684/0.679 V after the alert is on (3 cycles) | C15: 3 | D15: 0 | E15: =IF(C15=0,0,1-D15/C15) -> 1 | F15: T-03
A16: Crosstalk margin | B16: Contaminated reads tolerated after a channel switch | C16: 1 | D16: 2 | E16: =IF(C16=0,0,D16/C16) -> 2 | F16: A-05, A-06
A17: RAM headroom | B17: Free RAM at peak stack (bytes) | C17: ='Memory & Timing'!B12 -> 596 | D17: ='Memory & Timing'!C12 -> 1565 | E17: =IF(C17=0,0,D17/C17) -> 2.6258389 | F17: M-02
A18: Timing precision | B18: Measurement period (ms) | C18: 573 | D18: 560 | E18: Exactly 560 ms (was 573 ms) | F18: S-01, S-03
A19: Self-recovery | B19: Time to recover from a firmware hang (ms) | C19: Never (hangs) | D19: 2029 | E19: Recovers automatically | F19: W-01
A20: Smooth voltage calibration | B20: Places where a rising voltage makes the display step back (fine sweep) | C20: 2 | D20: 0 | E20: =IF(C20=0,0,1-D20/C20) -> 1 | F20: V-09, F-02, F-03
A21: Improvement = 1 - v1.0.0 / v0.3.0 for "fewer" rows, v1.0.0 / v0.3.0 for "x" rows.

Sheet Test Cases
A1: Test cases and results
A2: Results for v1.0.0 and v0.3.0. Source: simulated ATmega328P test runs (see Method).
A4: ID | B4: Group | C4: Test | D4: Stimulus | E4: Expected (v1.0.0) | F4: v0.3.0 result | G4: v1.0.0 result | H4: Status | I4: Method
A5: B-01 | B5: Build | C5: Production build compiles (DEBUG_FLAG 0) | D5: avr-gcc 7.3.0, strict C++ (no IDE auto-prototypes), -Wall -Wextra | E5: No errors, no warnings | F5: Compiles only with IDE auto-prototypes | G5: No errors, no warnings. 9,358 B flash, 273 B SRAM | H5: PASS | I5: Compiler
A6: B-02 | B6: Build | C6: Debug build compiles (DEBUG_FLAG 1) | D6: Same, DEBUG_FLAG 1 | E6: No errors, no warnings | F6: n/a (no debug mode) | G6: No errors, no warnings. 10,358 B flash, 287 B SRAM | H6: PASS | I6: Compiler
A7: B-03 | B7: Build | C7: Release file is set to production | D7: Check DEBUG_FLAG in the file to be flashed | E7: DEBUG_FLAG 0 | F7: n/a | G7: DEBUG_FLAG 0 | H7: PASS | I7: Code review
A8: B-04 | B8: Build | C8: Compile-time checks | D8: static_assert: table size 501, alert OFF < ON, sample counts <= 64 | E8: All hold | F8: None present | G8: All hold | H8: PASS | I8: Compiler
A9: I-01 | B9: Startup | C9: External reference selected before first ADC read | D9: Record order of analogReference / analogRead | E9: analogReference(EXTERNAL) before any analogRead | F9: OK (set in setup, reads in loop) | G9: OK (first line of setup) | H9: PASS | I9: Simulation
A10: I-02 | B10: Startup | C10: Analog inputs A0-A3 configured | D10: Record pinMode calls | E10: INPUT, no pull-up | F10: INPUT | G10: INPUT | H10: PASS | I10: Simulation
A11: I-03 | B11: Startup | C11: Digital input buffers off on A0-A3 | D11: Read DIDR0 after setup | E11: DIDR0 = 0x0F | F11: DIDR0 = 0x00 | G11: DIDR0 = 0x0F | H11: PASS | I11: Simulation
A12: I-04 | B12: Startup | C12: LED pins D3/D5 | D12: Record pinMode / digitalWrite | E12: OUTPUT, LOW at start | F12: OUTPUT (default LOW) | G12: OUTPUT, explicitly LOW | H12: PASS | I12: Simulation
A13: I-05 | B13: Startup | C13: Unused pins D2, D4, D6, A4, A5 | D13: Record pinMode | E13: INPUT_PULLUP (not floating) | F13: Not configured (floating) | G13: INPUT_PULLUP | H13: PASS | I13: Simulation
A14: I-06 | B14: Startup | C14: On-board LED D13 | D14: Record pinMode / digitalWrite | E14: OUTPUT, LOW | F14: Not configured | G14: OUTPUT, LOW | H14: PASS | I14: Simulation
A15: I-07 | B15: Startup | C15: No pinMode() on A6 (pin 20) | D15: Record pinMode calls; inspect pin tables in the binary | E15: Not called (A6 is analog-only, outside Arduino pin tables) | F15: Called: reads past pin table (no effect in this build) | G15: Not called | H15: PASS | I15: Simulation + binary inspection
... A105: V-12 | B105: Voltage | C105: Bench check against a Fluke 15B+ | D105: 10 points 0.8-20 V on the real supply, final firmware | E105: Every difference inside the Fluke tolerance | F105: n/a | G105: All 10 inside. Below 4 V (Fluke 1 mV range): -7 to -2 mV. Above 4 V the Fluke is not precise enough to decide (F-13) | H105: PASS | I105: Bench (hardware)

Sheet Unit Tests
A1: Unit tests: each firmware function called directly on the simulated chip
A2: Every result compared with an independent float32 model of the intended behavior. Run on the release file.
A4: Function | B4: What was tested | C4: Cases | D4: Mismatches | E4: Result
A5: readAdcAverage() | B5: Scripted sample sets: equal values, sort order, dropouts, spikes, limit 8/9 counts, two levels, random noise, 16 samples, 100 -> 64 cap, 1 sample | C5: 15 | D5: 0 | E5: =IF(D5=0,"PASS","FAIL") -> PASS
A6: computeVoltage() | B6: Every 10 mV step boundary (steps 79-2017) x offsets -3.1..+5 mV x previous state (none, -2, -1, same, +1), plus OL and 0.790 V threshold edges | C6: 96962 | D6: 0 | E6: =IF(D6=0,"PASS","FAIL") -> PASS
A7: computeCurrent() | B7: Every table midpoint and entry x offsets ±1.6 mV x previous state, plus 4451 mV / ADC 911-912 OL edges | C7: 25001 | D7: 0 | E7: =IF(D7=0,"PASS","FAIL") -> PASS
A8: findNearestCurrentStep() | B8: 0 to 4,451 mV in 0.25 mV steps against a plain nearest-value search | C8: 17805 | D8: 0 | E8: =IF(D8=0,"PASS","FAIL") -> PASS
A9: formatChannelRow() | B9: Every reachable voltage (0.000, 0.790-20.110 V) and current value, and all OL combinations | C9: 2438 | D9: 0 | E9: =IF(D9=0,"PASS","FAIL") -> PASS
A10: computeVoltage() fine sweep | B10: ADC 0 to 1023 in 0.02 count steps, fresh state each point, against the float32 calibration-line model | C10: 51151 | D10: 0 | E10: =IF(D10=0,"PASS","FAIL") -> PASS
A11: computeVoltage() ramps | B11: ADC 0 to 1023 and back in 0.05 count steps with the hysteresis state carried over: matches model, 0 reversals, never more than 1 step | C11: 40922 | D11: 0 | E11: =IF(D11=0,"PASS","FAIL") -> PASS
A12: shouldVRefTemperatureAlertBeActive() | B12: Both states x 8 voltages around 0.670 and 0.680 V | C12: 16 | D12: 0 | E12: =IF(D12=0,"PASS","FAIL") -> PASS
A13: isAdjacentStep() | B13: NO_STEP, equal, ±1, ±2 and extreme values | C13: 12 | D13: 0 | E13: =IF(D13=0,"PASS","FAIL") -> PASS
A14: Total | C14: =SUM(C5:C13) -> 234322 | D14: =SUM(D5:D13) -> 0 | E14: =IF(D14=0,"PASS","FAIL") -> PASS
A16: readAdcAverage() with 0 samples would return NaN; the static_assert "At least one sample" prevents it at compile time. Unreachable previous states (current step 501) are excluded.

Sheet ADC Parity
A1: Full ADC parity: v0.3.0 vs v1.0.0, every code 0-1023
A2: Channel 1 row shown; channel 2 was identical in every step. Inputs are exact (noise-free) ADC codes. Voltage differences come from the calibration line that replaces the 7 offset bands.
A3: ADC counts per volt | C3: 204.7 | D3: Op-amp gain | F3: 4.036 | G3: Constants from the firmware (ADC_COUNTS_PER_VOLT, OP_AMP_GAIN). v1.0.0 then applies displayed = measured x 0.99578 + 31 mV.
A4: ADC code | B4: ADC pin (mV) | C4: Channel voltage (mV) | D4: v0.3.0 voltage (V) | E4: v1.0.0 voltage (V) | F4: Voltage result | G4: Current sense (mV) | H4: v0.3.0 current (A) | I4: v1.0.0 current (A) | J4: Current result | K4: v0.3.0 LED | L4: v1.0.0 LED | M4: LED result | N4: v0.3.0 LCD row (current sweep) | O4: v1.0.0 LCD row (current sweep)
A5: 0 | B5: =A5/$C$3*1000 -> 0 | C5: =B5*$F$3 -> 0 | D5: 0 | E5: 0 | F5: =IF(D5=E5,"Identical",IF(E5="OL","ADC full scale: now OL",IF(ABS(E5-D5)<0.0105,"Within 10 mV (calibration line)",IF(AND(C5<4200,ABS(E5-D5)<0.0205),"-20 mV (end of old +30 mV band)",IF(C5<830,"Low range fixed (F-02)","Different"))))) -> Identical | G5: =B5 -> 0 | H5: 0 | I5: 0 | J5: =IF(H5=I5,"Identical",IF(I5="OL","Above 5.00 A: now OL",IF(H5="ERR (999.23)","Gap bug fixed",IF(ABS(I5-H5-0.01)<0.0001,"+0.01 A (nearest step)","Different")))) -> Identical | K5: Off | L5: Off | M5: =IF(K5=L5,"Same","Different") -> Same | N5: |12.030V 0.000A | | O5: |12.030V 0.000A |
A6: 1 | B6: =A6/$C$3*1000 -> 4.8851979 | C6: =B6*$F$3 -> 19.716659 | D6: 0 | E6: 0 | F6: =IF(D6=E6,"Identical",IF(E6="OL","ADC full scale: now OL",IF(ABS(E6-D6)<0.0105,"Within 10 mV (calibration line)",IF(AND(C6<4200,ABS(E6-D6)<0.0205),"-20 mV (end of old +30 mV band)",IF(C6<830,"Low range fixed (F-02)","Different"))))) -> Identical | G6: =B6 -> 4.8851979 | H6: 0 | I6: 0 | J6: =IF(H6=I6,"Identical",IF(I6="OL","Above 5.00 A: now OL",IF(H6="ERR (999.23)","Gap bug fixed",IF(ABS(I6-H6-0.01)<0.0001,"+0.01 A (nearest step)","Different")))) -> Identical | K6: Off | L6: Off | M6: =IF(K6=L6,"Same","Different") -> Same | N6: |12.030V 0.000A | | O6: |12.030V 0.000A |
A7: 2 | B7: =A7/$C$3*1000 -> 9.7703957 | C7: =B7*$F$3 -> 39.433317 | D7: 0 | E7: 0 | F7: =IF(D7=E7,"Identical",IF(E7="OL","ADC full scale: now OL",IF(ABS(E7-D7)<0.0105,"Within 10 mV (calibration line)",IF(AND(C7<4200,ABS(E7-D7)<0.0205),"-20 mV (end of old +30 mV band)",IF(C7<830,"Low range fixed (F-02)","Different"))))) -> Identical | G7: =B7 -> 9.7703957 | H7: 0.01 | I7: 0.01 | J7: =IF(H7=I7,"Identical",IF(I7="OL","Above 5.00 A: now OL",IF(H7="ERR (999.23)","Gap bug fixed",IF(ABS(I7-H7-0.01)<0.0001,"+0.01 A (nearest step)","Different")))) -> Identical | K7: On | L7: On | M7: =IF(K7=L7,"Same","Different") -> Same | N7: |12.030V 0.010A | | O7: |12.030V 0.010A |
A8: 3 | B8: =A8/$C$3*1000 -> 14.655594 | C8: =B8*$F$3 -> 59.149976 | D8: 0 | E8: 0 | F8: =IF(D8=E8,"Identical",IF(E8="OL","ADC full scale: now OL",IF(ABS(E8-D8)<0.0105,"Within 10 mV (calibration line)",IF(AND(C8<4200,ABS(E8-D8)<0.0205),"-20 mV (end of old +30 mV band)",IF(C8<830,"Low range fixed (F-02)","Different"))))) -> Identical | G8: =B8 -> 14.655594 | H8: 0.01 | I8: 0.01 | J8: =IF(H8=I8,"Identical",IF(I8="OL","Above 5.00 A: now OL",IF(H8="ERR (999.23)","Gap bug fixed",IF(ABS(I8-H8-0.01)<0.0001,"+0.01 A (nearest step)","Different")))) -> Identical | K8: On | L8: On | M8: =IF(K8=L8,"Same","Different") -> Same | N8: |12.030V 0.010A | | O8: |12.030V 0.010A |
A9: 4 | B9: =A9/$C$3*1000 -> 19.540791 | C9: =B9*$F$3 -> 78.866634 | D9: 0 | E9: 0 | F9: =IF(D9=E9,"Identical",IF(E9="OL","ADC full scale: now OL",IF(ABS(E9-D9)<0.0105,"Within 10 mV (calibration line)",IF(AND(C9<4200,ABS(E9-D9)<0.0205),"-20 mV (end of old +30 mV band)",IF(C9<830,"Low range fixed (F-02)","Different"))))) -> Identical | G9: =B9 -> 19.540791 | H9: 0.02 | I9: 0.02 | J9: =IF(H9=I9,"Identical",IF(I9="OL","Above 5.00 A: now OL",IF(H9="ERR (999.23)","Gap bug fixed",IF(ABS(I9-H9-0.01)<0.0001,"+0.01 A (nearest step)","Different")))) -> Identical | K9: On | L9: On | M9: =IF(K9=L9,"Same","Different") -> Same | N9: |12.030V 0.020A | | O9: |12.030V 0.020A |
A10: 5 | B10: =A10/$C$3*1000 -> 24.425989 | C10: =B10*$F$3 -> 98.583293 | D10: 0 | E10: 0 | F10: =IF(D10=E10,"Identical",IF(E10="OL","ADC full scale: now OL",IF(ABS(E10-D10)<0.0105,"Within 10 mV (calibration line)",IF(AND(C10<4200,ABS(E10-D10)<0.0205),"-20 mV (end of old +30 mV band)",IF(C10<830,"Low range fixed (F-02)","Different"))))) -> Identical | G10: =B10 -> 24.425989 | H10: 0.02 | I10: 0.02 | J10: =IF(H10=I10,"Identical",IF(I10="OL","Above 5.00 A: now OL",IF(H10="ERR (999.23)","Gap bug fixed",IF(ABS(I10-H10-0.01)<0.0001,"+0.01 A (nearest step)","Different")))) -> Identical | K10: On | L10: On | M10: =IF(K10=L10,"Same","Different") -> Same | N10: |12.030V 0.020A | | O10: |12.030V 0.020A |
A11: 6 | B11: =A11/$C$3*1000 -> 29.311187 | C11: =B11*$F$3 -> 118.29995 | D11: 0 | E11: 0 | F11: =IF(D11=E11,"Identical",IF(E11="OL","ADC full scale: now OL",IF(ABS(E11-D11)<0.0105,"Within 10 mV (calibration line)",IF(AND(C11<4200,ABS(E11-D11)<0.0205),"-20 mV (end of old +30 mV band)",IF(C11<830,"Low range fixed (F-02)","Different"))))) -> Identical | G11: =B11 -> 29.311187 | H11: 0.03 | I11: 0.03 | J11: =IF(H11=I11,"Identical",IF(I11="OL","Above 5.00 A: now OL",IF(H11="ERR (999.23)","Gap bug fixed",IF(ABS(I11-H11-0.01)<0.0001,"+0.01 A (nearest step)","Different")))) -> Identical | K11: On | L11: On | M11: =IF(K11=L11,"Same","Different") -> Same | N11: |12.030V 0.030A | | O11: |12.030V 0.030A |
A12: 7 | B12: =A12/$C$3*1000 -> 34.196385 | C12: =B12*$F$3 -> 138.01661 | D12: 0 | E12: 0 | F12: =IF(D12=E12,"Identical",IF(E12="OL","ADC full scale: now OL",IF(ABS(E12-D12)<0.0105,"Within 10 mV (calibration line)",IF(AND(C12<4200,ABS(E12-D12)<0.0205),"-20 mV (end of old +30 mV band)",IF(C12<830,"Low range fixed (F-02)","Different"))))) -> Identical | G12: =B12 -> 34.196385 | H12: 0.03 | I12: 0.03 | J12: =IF(H12=I12,"Identical",IF(I12="OL","Above 5.00 A: now OL",IF(H12="ERR (999.23)","Gap bug fixed",IF(ABS(I12-H12-0.01)<0.0001,"+0.01 A (nearest step)","Different")))) -> Identical | K12: On | L12: On | M12: =IF(K12=L12,"Same","Different") -> Same | N12: |12.030V 0.030A | | O12: |12.030V 0.030A |
A13: 8 | B13: =A13/$C$3*1000 -> 39.081583 | C13: =B13*$F$3 -> 157.73327 | D13: 0 | E13: 0 | F13: =IF(D13=E13,"Identical",IF(E13="OL","ADC full scale: now OL",IF(ABS(E13-D13)<0.0105,"Within 10 mV (calibration line)",IF(AND(C13<4200,ABS(E13-D13)<0.0205),"-20 mV (end of old +30 mV band)",IF(C13<830,"Low range fixed (F-02)","Different"))))) -> Identical | G13: =B13 -> 39.081583 | H13: 0.04 | I13: 0.04 | J13: =IF(H13=I13,"Identical",IF(I13="OL","Above 5.00 A: now OL",IF(H13="ERR (999.23)","Gap bug fixed",IF(ABS(I13-H13-0.01)<0.0001,"+0.01 A (nearest step)","Different")))) -> Identical | K13: On | L13: On | M13: =IF(K13=L13,"Same","Different") -> Same | N13: |12.030V 0.040A | | O13: |12.030V 0.040A |
A14: 9 | B14: =A14/$C$3*1000 -> 43.966781 | C14: =B14*$F$3 -> 177.44993 | D14: 0 | E14: 0 | F14: =IF(D14=E14,"Identical",IF(E14="OL","ADC full scale: now OL",IF(ABS(E14-D14)<0.0105,"Within 10 mV (calibration line)",IF(AND(C14<4200,ABS(E14-D14)<0.0205),"-20 mV (end of old +30 mV band)",IF(C14<830,"Low range fixed (F-02)","Different"))))) -> Identical | G14: =B14 -> 43.966781 | H14: 0.04 | I14: 0.05 | J14: =IF(H14=I14,"Identical",IF(I14="OL","Above 5.00 A: now OL",IF(H14="ERR (999.23)","Gap bug fixed",IF(ABS(I14-H14-0.01)<0.0001,"+0.01 A (nearest step)","Different")))) -> +0.01 A (nearest step) | K14: On | L14: On | M14: =IF(K14=L14,"Same","Different") -> Same | N14: |12.030V 0.040A | | O14: |12.030V 0.050A |
A15: 10 | B15: =A15/$C$3*1000 -> 48.851979 | C15: =B15*$F$3 -> 197.16659 | D15: 0 | E15: 0 | F15: =IF(D15=E15,"Identical",IF(E15="OL","ADC full scale: now OL",IF(ABS(E15-D15)<0.0105,"Within 10 mV (calibration line)",IF(AND(C15<4200,ABS(E15-D15)<0.0205),"-20 mV (end of old +30 mV band)",IF(C15<830,"Low range fixed (F-02)","Different"))))) -> Identical | G15: =B15 -> 48.851979 | H15: 0.05 | I15: 0.05 | J15: =IF(H15=I15,"Identical",IF(I15="OL","Above 5.00 A: now OL",IF(H15="ERR (999.23)","Gap bug fixed",IF(ABS(I15-H15-0.01)<0.0001,"+0.01 A (nearest step)","Different")))) -> Identical | K15: On | L15: On | M15: =IF(K15=L15,"Same","Different") -> Same | N15: |12.030V 0.050A | | O15: |12.030V 0.050A |
A16: 11 | B16: =A16/$C$3*1000 -> 53.737176 | C16: =B16*$F$3 -> 216.88324 | D16: 0 | E16: 0 | F16: =IF(D16=E16,"Identical",IF(E16="OL","ADC full scale: now OL",IF(ABS(E16-D16)<0.0105,"Within 10 mV (calibration line)",IF(AND(C16<4200,ABS(E16-D16)<0.0205),"-20 mV (end of old +30 mV band)",IF(C16<830,"Low range fixed (F-02)","Different"))))) -> Identical | G16: =B16 -> 53.737176 | H16: 0.06 | I16: 0.06 | J16: =IF(H16=I16,"Identical",IF(I16="OL","Above 5.00 A: now OL",IF(H16="ERR (999.23)","Gap bug fixed",IF(ABS(I16-H16-0.01)<0.0001,"+0.01 A (nearest step)","Different")))) -> Identical | K16: On | L16: On | M16: =IF(K16=L16,"Same","Different") -> Same | N16: |12.030V 0.060A | | O16: |12.030V 0.060A |
... A459: 454 | B459: =A459/$C$3*1000 -> 2217.8798 | C459: =B459*$F$3 -> 8951.363 | D459: 8.94 | E459: 8.94 | F459: =IF(D459=E459,"Identical",IF(E459="OL","ADC full scale: now OL",IF(ABS(E459-D459)<0.0105,"Within 10 mV (calibration line)",IF(AND(C459<4200,ABS(E459-D459)<0.0205),"-20 mV (end of old +30 mV band)",IF(C459<830,"Low range fixed (F-02)","Different"))))) -> Identical | G459: =B459 -> 2217.8798 | H459: 2.49 | I459: 2.49 | J459: =IF(H459=I459,"Identical",IF(I459="OL","Above 5.00 A: now OL",IF(H459="ERR (999.23)","Gap bug fixed",IF(ABS(I459-H459-0.01)<0.0001,"+0.01 A (nearest step)","Different")))) -> Identical | K459: On | L459: On | M459: =IF(K459=L459,"Same","Different") -> Same | N459: |12.030V 2.490A | | O459: |12.030V 2.490A |
A460: 455 | B460: =A460/$C$3*1000 -> 2222.765 | C460: =B460*$F$3 -> 8971.0796 | D460: 8.96 | E460: 8.96 | F460: =IF(D460=E460,"Identical",IF(E460="OL","ADC full scale: now OL",IF(ABS(E460-D460)<0.0105,"Within 10 mV (calibration line)",IF(AND(C460<4200,ABS(E460-D460)<0.0205),"-20 mV (end of old +30 mV band)",IF(C460<830,"Low range fixed (F-02)","Different"))))) -> Identical | G460: =B460 -> 2222.765 | H460: ERR (999.23) | I460: 2.49 | J460: =IF(H460=I460,"Identical",IF(I460="OL","Above 5.00 A: now OL",IF(H460="ERR (999.23)","Gap bug fixed",IF(ABS(I460-H460-0.01)<0.0001,"+0.01 A (nearest step)","Different")))) -> Gap bug fixed | K460: Off | L460: On | M460: =IF(K460=L460,"Same","Different") -> Different | N460: |12.030V 999.2A0| | O460: |12.030V 2.490A |
A461: 456 | B461: =A461/$C$3*1000 -> 2227.6502 | C461: =B461*$F$3 -> 8990.7963 | D461: 8.98 | E461: 8.98 | F461: =IF(D461=E461,"Identical",IF(E461="OL","ADC full scale: now OL",IF(ABS(E461-D461)<0.0105,"Within 10 mV (calibration line)",IF(AND(C461<4200,ABS(E461-D461)<0.0205),"-20 mV (end of old +30 mV band)",IF(C461<830,"Low range fixed (F-02)","Different"))))) -> Identical | G461: =B461 -> 2227.6502 | H461: ERR (999.23) | I461: 2.5 | J461: =IF(H461=I461,"Identical",IF(I461="OL","Above 5.00 A: now OL",IF(H461="ERR (999.23)","Gap bug fixed",IF(ABS(I461-H461-0.01)<0.0001,"+0.01 A (nearest step)","Different")))) -> Gap bug fixed | K461: Off | L461: On | M461: =IF(K461=L461,"Same","Different") -> Different | N461: |12.030V 999.2A0| | O461: |12.030V 2.500A |
A462: 457 | B462: =A462/$C$3*1000 -> 2232.5354 | C462: =B462*$F$3 -> 9010.5129 | D462: 9 | E462: 9 | F462: =IF(D462=E462,"Identical",IF(E462="OL","ADC full scale: now OL",IF(ABS(E462-D462)<0.0105,"Within 10 mV (calibration line)",IF(AND(C462<4200,ABS(E462-D462)<0.0205),"-20 mV (end of old +30 mV band)",IF(C462<830,"Low range fixed (F-02)","Different"))))) -> Identical | G462: =B462 -> 2232.5354 | H462: 2.5 | I462: 2.51 | J462: =IF(H462=I462,"Identical",IF(I462="OL","Above 5.00 A: now OL",IF(H462="ERR (999.23)","Gap bug fixed",IF(ABS(I462-H462-0.01)<0.0001,"+0.01 A (nearest step)","Different")))) -> +0.01 A (nearest step) | K462: On | L462: On | M462: =IF(K462=L462,"Same","Different") -> Same | N462: |12.030V 2.500A0| | O462: |12.030V 2.510A |
A463: 458 | B463: =A463/$C$3*1000 -> 2237.4206 | C463: =B463*$F$3 -> 9030.2296 | D463: 9.02 | E463: 9.02 | F463: =IF(D463=E463,"Identical",IF(E463="OL","ADC full scale: now OL",IF(ABS(E463-D463)<0.0105,"Within 10 mV (calibration line)",IF(AND(C463<4200,ABS(E463-D463)<0.0205),"-20 mV (end of old +30 mV band)",IF(C463<830,"Low range fixed (F-02)","Different"))))) -> Identical | G463: =B463 -> 2237.4206 | H463: 2.51 | I463: 2.51 | J463: =IF(H463=I463,"Identical",IF(I463="OL","Above 5.00 A: now OL",IF(H463="ERR (999.23)","Gap bug fixed",IF(ABS(I463-H463-0.01)<0.0001,"+0.01 A (nearest step)","Different")))) -> Identical | K463: On | L463: On | M463: =IF(K463=L463,"Same","Different") -> Same | N463: |12.030V 2.510A0| | O463: |12.030V 2.510A |
A464: 459 | B464: =A464/$C$3*1000 -> 2242.3058 | C464: =B464*$F$3 -> 9049.9463 | D464: 9.03 | E464: 9.04 | F464: =IF(D464=E464,"Identical",IF(E464="OL","ADC full scale: now OL",IF(ABS(E464-D464)<0.0105,"Within 10 mV (calibration line)",IF(AND(C464<4200,ABS(E464-D464)<0.0205),"-20 mV (end of old +30 mV band)",IF(C464<830,"Low range fixed (F-02)","Different"))))) -> Within 10 mV (calibration line) | G464: =B464 -> 2242.3058 | H464: 2.52 | I464: 2.52 | J464: =IF(H464=I464,"Identical",IF(I464="OL","Above 5.00 A: now OL",IF(H464="ERR (999.23)","Gap bug fixed",IF(ABS(I464-H464-0.01)<0.0001,"+0.01 A (nearest step)","Different")))) -> Identical | K464: On | L464: On | M464: =IF(K464=L464,"Same","Different") -> Same | N464: |12.030V 2.520A0| | O464: |12.030V 2.520A |
A465: 460 | B465: =A465/$C$3*1000 -> 2247.191 | C465: =B465*$F$3 -> 9069.6629 | D465: 9.05 | E465: 9.06 | F465: =IF(D465=E465,"Identical",IF(E465="OL","ADC full scale: now OL",IF(ABS(E465-D465)<0.0105,"Within 10 mV (calibration line)",IF(AND(C465<4200,ABS(E465-D465)<0.0205),"-20 mV (end of old +30 mV band)",IF(C465<830,"Low range fixed (F-02)","Different"))))) -> Within 10 mV (calibration line) | G465: =B465 -> 2247.191 | H465: 2.52 | I465: 2.52 | J465: =IF(H465=I465,"Identical",IF(I465="OL","Above 5.00 A: now OL",IF(H465="ERR (999.23)","Gap bug fixed",IF(ABS(I465-H465-0.01)<0.0001,"+0.01 A (nearest step)","Different")))) -> Identical | K465: On | L465: On | M465: =IF(K465=L465,"Same","Different") -> Same | N465: |12.030V 2.520A0| | O465: |12.030V 2.520A |
A466: 461 | B466: =A466/$C$3*1000 -> 2252.0762 | C466: =B466*$F$3 -> 9089.3796 | D466: 9.07 | E466: 9.08 | F466: =IF(D466=E466,"Identical",IF(E466="OL","ADC full scale: now OL",IF(ABS(E466-D466)<0.0105,"Within 10 mV (calibration line)",IF(AND(C466<4200,ABS(E466-D466)<0.0205),"-20 mV (end of old +30 mV band)",IF(C466<830,"Low range fixed (F-02)","Different"))))) -> Within 10 mV (calibration line) | G466: =B466 -> 2252.0762 | H466: 2.53 | I466: 2.53 | J466: =IF(H466=I466,"Identical",IF(I466="OL","Above 5.00 A: now OL",IF(H466="ERR (999.23)","Gap bug fixed",IF(ABS(I466-H466-0.01)<0.0001,"+0.01 A (nearest step)","Different")))) -> Identical | K466: On | L466: On | M466: =IF(K466=L466,"Same","Different") -> Same | N466: |12.030V 2.530A0| | O466: |12.030V 2.530A |
A467: 462 | B467: =A467/$C$3*1000 -> 2256.9614 | C467: =B467*$F$3 -> 9109.0962 | D467: 9.09 | E467: 9.1 | F467: =IF(D467=E467,"Identical",IF(E467="OL","ADC full scale: now OL",IF(ABS(E467-D467)<0.0105,"Within 10 mV (calibration line)",IF(AND(C467<4200,ABS(E467-D467)<0.0205),"-20 mV (end of old +30 mV band)",IF(C467<830,"Low range fixed (F-02)","Different"))))) -> Within 10 mV (calibration line) | G467: =B467 -> 2256.9614 | H467: 2.53 | I467: 2.53 | J467: =IF(H467=I467,"Identical",IF(I467="OL","Above 5.00 A: now OL",IF(H467="ERR (999.23)","Gap bug fixed",IF(ABS(I467-H467-0.01)<0.0001,"+0.01 A (nearest step)","Different")))) -> Identical | K467: On | L467: On | M467: =IF(K467=L467,"Same","Different") -> Same | N467: |12.030V 2.530A0| | O467: |12.030V 2.530A |
A468: 463 | B468: =A468/$C$3*1000 -> 2261.8466 | C468: =B468*$F$3 -> 9128.8129 | D468: 9.11 | E468: 9.12 | F468: =IF(D468=E468,"Identical",IF(E468="OL","ADC full scale: now OL",IF(ABS(E468-D468)<0.0105,"Within 10 mV (calibration line)",IF(AND(C468<4200,ABS(E468-D468)<0.0205),"-20 mV (end of old +30 mV band)",IF(C468<830,"Low range fixed (F-02)","Different"))))) -> Within 10 mV (calibration line) | G468: =B468 -> 2261.8466 | H468: 2.54 | I468: 2.54 | J468: =IF(H468=I468,"Identical",IF(I468="OL","Above 5.00 A: now OL",IF(H468="ERR (999.23)","Gap bug fixed",IF(ABS(I468-H468-0.01)<0.0001,"+0.01 A (nearest step)","Different")))) -> Identical | K468: On | L468: On | M468: =IF(K468=L468,"Same","Different") -> Same | N468: |12.030V 2.540A0| | O468: |12.030V 2.540A |
A469: 464 | B469: =A469/$C$3*1000 -> 2266.7318 | C469: =B469*$F$3 -> 9148.5296 | D469: 9.13 | E469: 9.14 | F469: =IF(D469=E469,"Identical",IF(E469="OL","ADC full scale: now OL",IF(ABS(E469-D469)<0.0105,"Within 10 mV (calibration line)",IF(AND(C469<4200,ABS(E469-D469)<0.0205),"-20 mV (end of old +30 mV band)",IF(C469<830,"Low range fixed (F-02)","Different"))))) -> Within 10 mV (calibration line) | G469: =B469 -> 2266.7318 | H469: 2.54 | I469: 2.54 | J469: =IF(H469=I469,"Identical",IF(I469="OL","Above 5.00 A: now OL",IF(H469="ERR (999.23)","Gap bug fixed",IF(ABS(I469-H469-0.01)<0.0001,"+0.01 A (nearest step)","Different")))) -> Identical | K469: On | L469: On | M469: =IF(K469=L469,"Same","Different") -> Same | N469: |12.030V 2.540A0| | O469: |12.030V 2.540A |
A470: 465 | B470: =A470/$C$3*1000 -> 2271.617 | C470: =B470*$F$3 -> 9168.2462 | D470: 9.15 | E470: 9.16 | F470: =IF(D470=E470,"Identical",IF(E470="OL","ADC full scale: now OL",IF(ABS(E470-D470)<0.0105,"Within 10 mV (calibration line)",IF(AND(C470<4200,ABS(E470-D470)<0.0205),"-20 mV (end of old +30 mV band)",IF(C470<830,"Low range fixed (F-02)","Different"))))) -> Within 10 mV (calibration line) | G470: =B470 -> 2271.617 | H470: 2.55 | I470: 2.55 | J470: =IF(H470=I470,"Identical",IF(I470="OL","Above 5.00 A: now OL",IF(H470="ERR (999.23)","Gap bug fixed",IF(ABS(I470-H470-0.01)<0.0001,"+0.01 A (nearest step)","Different")))) -> Identical | K470: On | L470: On | M470: =IF(K470=L470,"Same","Different") -> Same | N470: |12.030V 2.550A0| | O470: |12.030V 2.550A |
A471: 466 | B471: =A471/$C$3*1000 -> 2276.5022 | C471: =B471*$F$3 -> 9187.9629 | D471: 9.17 | E471: 9.18 | F471: =IF(D471=E471,"Identical",IF(E471="OL","ADC full scale: now OL",IF(ABS(E471-D471)<0.0105,"Within 10 mV (calibration line)",IF(AND(C471<4200,ABS(E471-D471)<0.0205),"-20 mV (end of old +30 mV band)",IF(C471<830,"Low range fixed (F-02)","Different"))))) -> Within 10 mV (calibration line) | G471: =B471 -> 2276.5022 | H471: 2.55 | I471: 2.56 | J471: =IF(H471=I471,"Identical",IF(I471="OL","Above 5.00 A: now OL",IF(H471="ERR (999.23)","Gap bug fixed",IF(ABS(I471-H471-0.01)<0.0001,"+0.01 A (nearest step)","Different")))) -> +0.01 A (nearest step) | K471: On | L471: On | M471: =IF(K471=L471,"Same","Different") -> Same | N471: |12.030V 2.550A0| | O471: |12.030V 2.560A |
A472: 467 | B472: =A472/$C$3*1000 -> 2281.3874 | C472: =B472*$F$3 -> 9207.6795 | D472: 9.19 | E472: 9.2 | F472: =IF(D472=E472,"Identical",IF(E472="OL","ADC full scale: now OL",IF(ABS(E472-D472)<0.0105,"Within 10 mV (calibration line)",IF(AND(C472<4200,ABS(E472-D472)<0.0205),"-20 mV (end of old +30 mV band)",IF(C472<830,"Low range fixed (F-02)","Different"))))) -> Within 10 mV (calibration line) | G472: =B472 -> 2281.3874 | H472: 2.56 | I472: 2.56 | J472: =IF(H472=I472,"Identical",IF(I472="OL","Above 5.00 A: now OL",IF(H472="ERR (999.23)","Gap bug fixed",IF(ABS(I472-H472-0.01)<0.0001,"+0.01 A (nearest step)","Different")))) -> Identical | K472: On | L472: On | M472: =IF(K472=L472,"Same","Different") -> Same | N472: |12.030V 2.560A0| | O472: |12.030V 2.560A |
A473: 468 | B473: =A473/$C$3*1000 -> 2286.2726 | C473: =B473*$F$3 -> 9227.3962 | D473: 9.21 | E473: 9.22 | F473: =IF(D473=E473,"Identical",IF(E473="OL","ADC full scale: now OL",IF(ABS(E473-D473)<0.0105,"Within 10 mV (calibration line)",IF(AND(C473<4200,ABS(E473-D473)<0.0205),"-20 mV (end of old +30 mV band)",IF(C473<830,"Low range fixed (F-02)","Different"))))) -> Within 10 mV (calibration line) | G473: =B473 -> 2286.2726 | H473: 2.57 | I473: 2.57 | J473: =IF(H473=I473,"Identical",IF(I473="OL","Above 5.00 A: now OL",IF(H473="ERR (999.23)","Gap bug fixed",IF(ABS(I473-H473-0.01)<0.0001,"+0.01 A (nearest step)","Different")))) -> Identical | K473: On | L473: On | M473: =IF(K473=L473,"Same","Different") -> Same | N473: |12.030V 2.570A0| | O473: |12.030V 2.570A |
... A916: 911 | B916: =A916/$C$3*1000 -> 4450.4152 | C916: =B916*$F$3 -> 17961.876 | D916: 17.92 | E916: 17.92 | F916: =IF(D916=E916,"Identical",IF(E916="OL","ADC full scale: now OL",IF(ABS(E916-D916)<0.0105,"Within 10 mV (calibration line)",IF(AND(C916<4200,ABS(E916-D916)<0.0205),"-20 mV (end of old +30 mV band)",IF(C916<830,"Low range fixed (F-02)","Different"))))) -> Identical | G916: =B916 -> 4450.4152 | H916: 5 | I916: 5 | J916: =IF(H916=I916,"Identical",IF(I916="OL","Above 5.00 A: now OL",IF(H916="ERR (999.23)","Gap bug fixed",IF(ABS(I916-H916-0.01)<0.0001,"+0.01 A (nearest step)","Different")))) -> Identical | K916: On | L916: On | M916: =IF(K916=L916,"Same","Different") -> Same | N916: |12.030V 5.000A0| | O916: |12.030V 5.000A |
A917: 912 | B917: =A917/$C$3*1000 -> 4455.3004 | C917: =B917*$F$3 -> 17981.593 | D917: 17.94 | E917: 17.94 | F917: =IF(D917=E917,"Identical",IF(E917="OL","ADC full scale: now OL",IF(ABS(E917-D917)<0.0105,"Within 10 mV (calibration line)",IF(AND(C917<4200,ABS(E917-D917)<0.0205),"-20 mV (end of old +30 mV band)",IF(C917<830,"Low range fixed (F-02)","Different"))))) -> Identical | G917: =B917 -> 4455.3004 | H917: ERR (999.23) | I917: OL | J917: =IF(H917=I917,"Identical",IF(I917="OL","Above 5.00 A: now OL",IF(H917="ERR (999.23)","Gap bug fixed",IF(ABS(I917-H917-0.01)<0.0001,"+0.01 A (nearest step)","Different")))) -> Above 5.00 A: now OL | K917: Off | L917: On | M917: =IF(K917=L917,"Same","Different") -> Different | N917: |12.030V 999.2A0| | O917: |12.030V OL |
A918: 913 | B918: =A918/$C$3*1000 -> 4460.1856 | C918: =B918*$F$3 -> 18001.309 | D918: 17.96 | E918: 17.96 | F918: =IF(D918=E918,"Identical",IF(E918="OL","ADC full scale: now OL",IF(ABS(E918-D918)<0.0105,"Within 10 mV (calibration line)",IF(AND(C918<4200,ABS(E918-D918)<0.0205),"-20 mV (end of old +30 mV band)",IF(C918<830,"Low range fixed (F-02)","Different"))))) -> Identical | G918: =B918 -> 4460.1856 | H918: ERR (999.23) | I918: OL | J918: =IF(H918=I918,"Identical",IF(I918="OL","Above 5.00 A: now OL",IF(H918="ERR (999.23)","Gap bug fixed",IF(ABS(I918-H918-0.01)<0.0001,"+0.01 A (nearest step)","Different")))) -> Above 5.00 A: now OL | K918: Off | L918: On | M918: =IF(K918=L918,"Same","Different") -> Different | N918: |12.030V 999.2A0| | O918: |12.030V OL |
A919: 914 | B919: =A919/$C$3*1000 -> 4465.0708 | C919: =B919*$F$3 -> 18021.026 | D919: 17.98 | E919: 17.98 | F919: =IF(D919=E919,"Identical",IF(E919="OL","ADC full scale: now OL",IF(ABS(E919-D919)<0.0105,"Within 10 mV (calibration line)",IF(AND(C919<4200,ABS(E919-D919)<0.0205),"-20 mV (end of old +30 mV band)",IF(C919<830,"Low range fixed (F-02)","Different"))))) -> Identical | G919: =B919 -> 4465.0708 | H919: ERR (999.23) | I919: OL | J919: =IF(H919=I919,"Identical",IF(I919="OL","Above 5.00 A: now OL",IF(H919="ERR (999.23)","Gap bug fixed",IF(ABS(I919-H919-0.01)<0.0001,"+0.01 A (nearest step)","Different")))) -> Above 5.00 A: now OL | K919: Off | L919: On | M919: =IF(K919=L919,"Same","Different") -> Different | N919: |12.030V 999.2A0| | O919: |12.030V OL |
A920: 915 | B920: =A920/$C$3*1000 -> 4469.956 | C920: =B920*$F$3 -> 18040.743 | D920: 18 | E920: 18 | F920: =IF(D920=E920,"Identical",IF(E920="OL","ADC full scale: now OL",IF(ABS(E920-D920)<0.0105,"Within 10 mV (calibration line)",IF(AND(C920<4200,ABS(E920-D920)<0.0205),"-20 mV (end of old +30 mV band)",IF(C920<830,"Low range fixed (F-02)","Different"))))) -> Identical | G920: =B920 -> 4469.956 | H920: ERR (999.23) | I920: OL | J920: =IF(H920=I920,"Identical",IF(I920="OL","Above 5.00 A: now OL",IF(H920="ERR (999.23)","Gap bug fixed",IF(ABS(I920-H920-0.01)<0.0001,"+0.01 A (nearest step)","Different")))) -> Above 5.00 A: now OL | K920: Off | L920: On | M920: =IF(K920=L920,"Same","Different") -> Different | N920: |12.030V 999.2A0| | O920: |12.030V OL |
A921: 916 | B921: =A921/$C$3*1000 -> 4474.8412 | C921: =B921*$F$3 -> 18060.459 | D921: 18.02 | E921: 18.02 | F921: =IF(D921=E921,"Identical",IF(E921="OL","ADC full scale: now OL",IF(ABS(E921-D921)<0.0105,"Within 10 mV (calibration line)",IF(AND(C921<4200,ABS(E921-D921)<0.0205),"-20 mV (end of old +30 mV band)",IF(C921<830,"Low range fixed (F-02)","Different"))))) -> Identical | G921: =B921 -> 4474.8412 | H921: ERR (999.23) | I921: OL | J921: =IF(H921=I921,"Identical",IF(I921="OL","Above 5.00 A: now OL",IF(H921="ERR (999.23)","Gap bug fixed",IF(ABS(I921-H921-0.01)<0.0001,"+0.01 A (nearest step)","Different")))) -> Above 5.00 A: now OL | K921: Off | L921: On | M921: =IF(K921=L921,"Same","Different") -> Different | N921: |12.030V 999.2A0| | O921: |12.030V OL |
A922: 917 | B922: =A922/$C$3*1000 -> 4479.7264 | C922: =B922*$F$3 -> 18080.176 | D922: 18.04 | E922: 18.03 | F922: =IF(D922=E922,"Identical",IF(E922="OL","ADC full scale: now OL",IF(ABS(E922-D922)<0.0105,"Within 10 mV (calibration line)",IF(AND(C922<4200,ABS(E922-D922)<0.0205),"-20 mV (end of old +30 mV band)",IF(C922<830,"Low range fixed (F-02)","Different"))))) -> Within 10 mV (calibration line) | G922: =B922 -> 4479.7264 | H922: ERR (999.23) | I922: OL | J922: =IF(H922=I922,"Identical",IF(I922="OL","Above 5.00 A: now OL",IF(H922="ERR (999.23)","Gap bug fixed",IF(ABS(I922-H922-0.01)<0.0001,"+0.01 A (nearest step)","Different")))) -> Above 5.00 A: now OL | K922: Off | L922: On | M922: =IF(K922=L922,"Same","Different") -> Different | N922: |12.030V 999.2A0| | O922: |12.030V OL |
A923: 918 | B923: =A923/$C$3*1000 -> 4484.6116 | C923: =B923*$F$3 -> 18099.893 | D923: 18.05 | E923: 18.05 | F923: =IF(D923=E923,"Identical",IF(E923="OL","ADC full scale: now OL",IF(ABS(E923-D923)<0.0105,"Within 10 mV (calibration line)",IF(AND(C923<4200,ABS(E923-D923)<0.0205),"-20 mV (end of old +30 mV band)",IF(C923<830,"Low range fixed (F-02)","Different"))))) -> Identical | G923: =B923 -> 4484.6116 | H923: ERR (999.23) | I923: OL | J923: =IF(H923=I923,"Identical",IF(I923="OL","Above 5.00 A: now OL",IF(H923="ERR (999.23)","Gap bug fixed",IF(ABS(I923-H923-0.01)<0.0001,"+0.01 A (nearest step)","Different")))) -> Above 5.00 A: now OL | K923: Off | L923: On | M923: =IF(K923=L923,"Same","Different") -> Different | N923: |12.030V 999.2A0| | O923: |12.030V OL |
A924: 919 | B924: =A924/$C$3*1000 -> 4489.4968 | C924: =B924*$F$3 -> 18119.609 | D924: 18.07 | E924: 18.07 | F924: =IF(D924=E924,"Identical",IF(E924="OL","ADC full scale: now OL",IF(ABS(E924-D924)<0.0105,"Within 10 mV (calibration line)",IF(AND(C924<4200,ABS(E924-D924)<0.0205),"-20 mV (end of old +30 mV band)",IF(C924<830,"Low range fixed (F-02)","Different"))))) -> Identical | G924: =B924 -> 4489.4968 | H924: ERR (999.23) | I924: OL | J924: =IF(H924=I924,"Identical",IF(I924="OL","Above 5.00 A: now OL",IF(H924="ERR (999.23)","Gap bug fixed",IF(ABS(I924-H924-0.01)<0.0001,"+0.01 A (nearest step)","Different")))) -> Above 5.00 A: now OL | K924: Off | L924: On | M924: =IF(K924=L924,"Same","Different") -> Different | N924: |12.030V 999.2A0| | O924: |12.030V OL |
...

Sheet Stability Tests
A1: Display stability and resolution tests
A2: Each noise scenario is 300 measurement cycles (about 2.8 minutes of operation). Changes = number of times the displayed value changed.
A4: Scenario | B4: Stimulus | C4: Cycles | D4: v0.3.0 changes | E4: v1.0.0 changes, outlier rejection off (limit 1023) | F4: v1.0.0 changes | G4: v0.3.0 values shown (count) | H4: v1.0.0 values shown, outlier rejection off | I4: v1.0.0 values shown
A5: Voltage on a 10 mV boundary | B5: ADC 611.40 (12.035 V after calibration, a v1.0.0 step boundary), uniform ±1 count noise | C5: 300 | D5: 158 | E5: 3 | F5: 3 | G5: 12.01: 18, 12.03: 160, 12.05: 122 | H5: 12.03: 132, 12.04: 168 | I5: 12.03: 132, 12.04: 168
A6: Voltage inside a 10 mV step | B6: ADC 611.15 (12.030 V), uniform ±1 count noise | C6: 300 | D6: 188 | E6: 0 | F6: 0 | G6: 12.01: 49, 12.03: 151, 12.05: 100 | H6: 12.03: 300 | I6: 12.03: 300
A7: Current on the 0.71/0.72 A boundary | B7: ADC 130.70 (638.5 mV), uniform ±1 count noise | C7: 300 | D7: 142 | E7: 1 | F7: 1 | G7: 0.71: 121, 0.72: 179 | H7: 0.71: 89, 0.72: 211 | I7: 0.71: 89, 0.72: 211
A8: Current 0.72 A inside a step | B8: ADC 131.62 (643 mV), uniform ±1 count noise | C8: 300 | D8: 30 | E8: 0 | F8: 0 | G8: 0.72: 285, 0.73: 15 | H8: 0.72: 300 | I8: 0.72: 300
A9: Current 0.72 A with sample dropouts (original symptom) | B9: ADC 131.62, ±0.5 count noise, 2% of samples replaced by ADC 4 (0.02 A) | C9: 300 | D9: 10 | E9: 215 | F9: 0 | G9: 0.02: 5, 0.72: 295 | H9: 0.65: 1, 0.66: 1, 0.67: 14, 0.68: 15, 0.69: 10, 0.7: 77, 0.71: 111, 0.72: 71 | I9: 0.72: 300
A10: Totals | D10: =SUM(D5:D9) -> 528 | E10: =SUM(E5:E9) -> 219 | F10: =SUM(F5:F9) -> 4 | G10: Display changes avoided by v1.0.0 vs v0.3.0: | H10: =IF(D10=0,0,1-F10/D10) -> 0.99242424
A13: Slow ramps (input changes by 0.1 ADC count per cycle, then back down)
A14: Ramp | B14: Direction | C14: Cycles | D14: Ideal changes | E14: v0.3.0 changes | F14: v1.0.0 changes | G14: v0.3.0 max error vs ideal | H14: v1.0.0 max error vs ideal | I14: Comment
A15: I 0.49-0.78 A (codes 100-160) | B15: up | C15: 601 | D15: 34 | E15: 33 | F15: 33 | G15: 0.01 | H15: 0.01 | I15: Both follow the input; v1.0.0 holds a step only inside the 1.5 mV hysteresis band.
A16: I 0.49-0.78 A (codes 100-160) | B16: down | C16: 601 | D16: 34 | E16: 33 | F16: 33 | G16: 0.01 | H16: 0.01
A17: V 3.9-5.1 V (codes 200-260) | B17: up | C17: 601 | D17: 118 | E17: 59 | F17: 117 | G17: 0.01 | H17: 0.01 | I17: v0.3.0 skips every other 10 mV value (1 ADC count = 19.7 mV). v1.0.0 shows every value (3.960-5.130 V after calibration), never against the input: the 4.150 V band-edge reversal is gone.
A18: V 3.9-5.1 V (codes 200-260) | B18: down | C18: 601 | D18: 118 | E18: 59 | F18: 117 | G18: 0.01 | H18: 0.01
A19: V 0.71-0.95 V low range (codes 36-48) | B19: up | C19: 241 | D19: 19 | E19: 9 | F19: 19 | G19: 0.79 | H19: 0.01 | I19: v0.3.0 can never show 0.820 or 0.830 and runs backwards at 0.800 V. v1.0.0 shows 0.000 up to 0.790 V after calibration, then every 10 mV value in order. Ideal changes now count the calibrated values.
A20: V 0.71-0.95 V low range (codes 36-48) | B20: down | C20: 241 | D20: 19 | E20: 9 | F20: 19 | G20: 0.79 | H20: 0.01
A23: Outlier rejection: behavior outside the tested firmware scenarios (Python model, 4,000 trials each, same algorithm)
A24: Signal | B24: Description | D24: Plain average bias (counts) | E24: Plain average spread (counts) | F24: Outlier rejection bias (counts) | G24: Outlier rejection spread (counts) | H24: Better choice
A25: Normal noise ±2 counts | B25: Typical for this board | D25: 0.002 | E25: 0.145 | F25: 0.002 | G25: 0.145 | H25: Equal
A26: Noise ±8 counts | B26: At the rejection limit | D26: 0.023 | E26: 0.57 | F26: 0.069 | G26: 0.837 | H26: Plain average (slightly)
A27: Noise ±20 counts, symmetric | B27: Much noisier than expected | D27: -0.022 | E27: 1.445 | F27: 0.302 | G27: 3.094 | H27: Plain average
A28: Symmetric ripple ±15 counts | B28: Large real ripple at the ADC | D28: 0.004 | E28: 1.083 | F28: 0.234 | G28: 2.438 | H28: Plain average
A29: Asymmetric ripple: 10% of the time 30 counts low | B29: Real dips that are part of the true average | D29: 0.007 | E29: 1.135 | F29: 3 | G29: 0.077 | H29: Plain average
A30: 2% dropouts to 0 | B30: Isolated bad samples (original symptom) | D30: -10.083 | E30: 8.905 | F30: 0.002 | G30: 0.076 | H30: Outlier rejection
A31: 1 count = 4.9 mV at the ADC pin = 5.4 mA of current = 19.7 mV of channel voltage. Decide with bench test BT-43.

Sheet LCD Scenarios
A1: LCD, LED and screen-clear behavior in event scenarios
A2: Rows are exactly what the 16x2 LCD shows (top row = CH2, bottom row = CH1). LEDs = D3 (CH1) then D5 (CH2), 1 = on. Clears = lcd.clear() calls in the cycle.
A4: Scenario | B4: Step | C4: Stimulus | D4: v0.3.0 top row | E4: v0.3.0 bottom row | F4: v0.3.0 LEDs | G4: v0.3.0 clears | H4: v1.0.0 top row | I4: v1.0.0 bottom row | J4: v1.0.0 LEDs | K4: v1.0.0 clears | L4: Comment
A5: Over range | B5: 0 | C5: CH1 12.03 V / 0.72 A, CH2 12.03 V / 0.72 A | D5: |12.030V 0.720A0| | E5: |12.030V 0.720A0| | F5: 11 | G5: 0 | H5: |12.030V 0.720A | | I5: |12.030V 0.720A | | J5: 11 | K5: 0
A6: Over range | B6: 1 | C6: CH1 current ADC 1000 (above 5.00 A) | D6: |12.030V 0.720A0| | E6: |12.030V 999.2A0| | F6: 01 | G6: 0 | H6: |12.030V 0.720A | | I6: |12.030V OL | | J6: 11 | K6: 0 | L6: v0.3.0: garbage "999.2A0", LED off. v1.0.0: OL, LED on
A7: Over range | B7: 2 | C7: CH1 current back to 0.72 A | D7: |12.030V 0.720A0| | E7: |12.030V 0.720A0| | F7: 11 | G7: 0 | H7: |12.030V 0.720A | | I7: |12.030V 0.720A | | J7: 11 | K7: 0 | L7: v0.3.0 keeps a stale "0" in column 15
A8: Over range | B8: 3 | C8: CH1 voltage ADC 1023 (full scale) | D8: |12.030V 0.720A0| | E8: |20.130V 0.720A0| | F8: 11 | G8: 0 | H8: |12.030V 0.720A | | I8: | OL 0.720A | | J8: 11 | K8: 0 | L8: v0.3.0 shows 20.130V for an unknown voltage
A9: Over range | B9: 4 | C9: CH1 voltage back to 12.03 V | D9: |12.030V 0.720A0| | E9: |12.030V 0.720A0| | F9: 11 | G9: 0 | H9: |12.030V 0.720A | | I9: |12.030V 0.720A | | J9: 11 | K9: 0
A10: Over range | B10: 5 | C10: CH1 voltage and current both over range | D10: |12.030V 0.720A0| | E10: |20.130V 999.2A0| | F10: 01 | G10: 0 | H10: |12.030V 0.720A | | I10: | OL OL | | J10: 11 | K10: 0
A11: Over range | B11: 6 | C11: Both back to normal | D11: |12.030V 0.720A0| | E11: |12.030V 0.720A0| | F11: 11 | G11: 0 | H11: |12.030V 0.720A | | I11: |12.030V 0.720A | | J11: 11 | K11: 0
A12: Over range | B12: 7 | C12: CH1 current ADC 911 (5.00 A, last table value) | D12: |12.030V 0.720A0| | E12: |12.030V 5.000A0| | F12: 11 | G12: 0 | H12: |12.030V 0.720A | | I12: |12.030V 5.000A | | J12: 11 | K12: 0
A13: Over range | B13: 8 | C13: CH1 current ADC 912 (first code above 5.00 A) | D13: |12.030V 0.720A0| | E13: |12.030V 999.2A0| | F13: 01 | G13: 0 | H13: |12.030V 0.720A | | I13: |12.030V OL | | J13: 11 | K13: 0
A14: LED | B14: 0 | C14: CH1 current ADC 0 (0.00 A); CH2 ADC 254 / 0 A | D14: |5.0100V 0.000A0| | E14: |12.030V 0.000A0| | F14: 00 | G14: 0 | H14: | 5.020V 0.000A | | I14: |12.030V 0.000A | | J14: 00 | K14: 0
A15: LED | B15: 1 | C15: CH1 current ADC 1 (0.00 A (0.005 A, rounds to 0)); CH2 ADC 254 / 0 A | D15: |5.0100V 0.000A0| | E15: |12.030V 0.000A0| | F15: 00 | G15: 0 | H15: | 5.020V 0.000A | | I15: |12.030V 0.000A | | J15: 00 | K15: 0
A16: LED | B16: 2 | C16: CH1 current ADC 2 (0.01 A); CH2 ADC 254 / 0 A | D16: |5.0100V 0.000A0| | E16: |12.030V 0.010A0| | F16: 10 | G16: 0 | H16: | 5.020V 0.000A | | I16: |12.030V 0.010A | | J16: 10 | K16: 0
A17: LED | B17: 3 | C17: CH1 current ADC 3 (0.01 A); CH2 ADC 254 / 0 A | D17: |5.0100V 0.000A0| | E17: |12.030V 0.010A0| | F17: 10 | G17: 0 | H17: | 5.020V 0.000A | | I17: |12.030V 0.010A | | J17: 10 | K17: 0
A18: LED | B18: 4 | C18: CH1 current ADC 911 (5.00 A); CH2 ADC 254 / 0 A | D18: |5.0100V 0.000A0| | E18: |12.030V 5.000A0| | F18: 10 | G18: 0 | H18: | 5.020V 0.000A | | I18: |12.030V 5.000A | | J18: 10 | K18: 0
A19: LED | B19: 5 | C19: CH1 current ADC 912 (above 5.00 A); CH2 ADC 254 / 0 A | D19: |5.0100V 0.000A0| | E19: |12.030V 999.2A0| | F19: 00 | G19: 0 | H19: | 5.020V 0.000A | | I19: |12.030V OL | | J19: 10 | K19: 0 | L19: v0.3.0 LED off above 5.00 A; v1.0.0 LED on
A20: LED | B20: 6 | C20: CH1 current ADC 1023 (ADC full scale); CH2 ADC 254 / 0 A | D20: |5.0100V 0.000A0| | E20: |12.030V 999.2A0| | F20: 00 | G20: 0 | H20: | 5.020V 0.000A | | I20: |12.030V OL | | J20: 10 | K20: 0 | L20: v0.3.0 LED off above 5.00 A; v1.0.0 LED on
A21: LED | B21: 7 | C21: CH1 current ADC 0 (0.00 A); CH2 ADC 254 / 0 A | D21: |5.0100V 0.000A0| | E21: |12.030V 0.000A0| | F21: 00 | G21: 0 | H21: | 5.020V 0.000A | | I21: |12.030V 0.000A | | J21: 00 | K21: 0
A22: Temperature | B22: 0 | C22: Temperature pin 0.645 V (ADC 132) | D22: |5.0100V 0.000A0| | E22: |12.030V 0.720A0| | F22: 10 | G22: 0 | H22: | 5.020V 0.000A | | I22: |12.030V 0.720A | | J22: 10 | K22: 0
A23: Temperature | B23: 1 | C23: Temperature pin 0.645 V (ADC 132) | D23: |5.0100V 0.000A0| | E23: |12.030V 0.720A0| | F23: 10 | G23: 0 | H23: | 5.020V 0.000A | | I23: |12.030V 0.720A | | J23: 10 | K23: 0
A24: Temperature | B24: 2 | C24: Temperature pin 0.684 V (ADC 140) | D24: | IC6-TEMP | | E24: | ALERT | | F24: 10 | G24: 1 | H24: | VREF-TEMP | | I24: | ALERT | | J24: 10 | K24: 1 | L24: Alert on in both
A25: Temperature | B25: 3 | C25: Temperature pin 0.684 V (ADC 140) | D25: | IC6-TEMP | | E25: | ALERT | | F25: 10 | G25: 1 | H25: | VREF-TEMP | | I25: | ALERT | | J25: 10 | K25: 0
A26: Temperature | B26: 4 | C26: Temperature pin 0.679 V (ADC 139) | D26: |5.0100V-T0.000A | | E26: |12.030VLE0.720A | | F26: 10 | G26: 0 | H26: | VREF-TEMP | | I26: | ALERT | | J26: 10 | K26: 0 | L26: v0.3.0 alert off at 0.679 V and leftover "-T" / "LE"; v1.0.0 stays in alert (hysteresis)
A27: Temperature | B27: 5 | C27: Temperature pin 0.674 V (ADC 138) | D27: |5.0100V-T0.000A | | E27: |12.030VLE0.720A | | F27: 10 | G27: 0 | H27: | VREF-TEMP | | I27: | ALERT | | J27: 10 | K27: 0
A28: Temperature | B28: 6 | C28: Temperature pin 0.679 V (ADC 139) | D28: |5.0100V-T0.000A | | E28: |12.030VLE0.720A | | F28: 10 | G28: 0 | H28: | VREF-TEMP | | I28: | ALERT | | J28: 10 | K28: 0
A29: Temperature | B29: 7 | C29: Temperature pin 0.684 V (ADC 140) | D29: | IC6-TEMP | | E29: | ALERT | | F29: 10 | G29: 1 | H29: | VREF-TEMP | | I29: | ALERT | | J29: 10 | K29: 0
A30: Temperature | B30: 8 | C30: Temperature pin 0.674 V (ADC 138) | D30: |5.0100V-T0.000A | | E30: |12.030VLE0.720A | | F30: 10 | G30: 0 | H30: | VREF-TEMP | | I30: | ALERT | | J30: 10 | K30: 0
A31: Temperature | B31: 9 | C31: Temperature pin 0.669 V (ADC 137) | D31: |5.0100V-T0.000A | | E31: |12.030VLE0.720A | | F31: 10 | G31: 0 | H31: | 5.020V 0.000A | | I31: |12.030V 0.720A | | J31: 10 | K31: 1 | L31: v1.0.0 alert off below 0.670 V; screen cleared once, clean rows
A32: Temperature | B32: 10 | C32: Temperature pin 0.664 V (ADC 136) | D32: |5.0100V-T0.000A | | E32: |12.030VLE0.720A | | F32: 10 | G32: 0 | H32: | 5.020V 0.000A | | I32: |12.030V 0.720A | | J32: 10 | K32: 0
A33: Temperature | B33: 11 | C33: Temperature pin 0.645 V (ADC 132) | D33: |5.0100V-T0.000A | | E33: |12.030VLE0.720A | | F33: 10 | G33: 0 | H33: | 5.020V 0.000A | | I33: |12.030V 0.720A | | J33: 10 | K33: 0
A34: Temperature | B34: 12 | C34: Temperature pin 0.645 V (ADC 132) | D34: |5.0100V-T0.000A | | E34: |12.030VLE0.720A | | F34: 10 | G34: 0 | H34: | 5.020V 0.000A | | I34: |12.030V 0.720A | | J34: 10 | K34: 0
A35: Temperature | B35: 13 | C35: Temperature pin 0.684 V (ADC 140) | D35: | IC6-TEMP | | E35: | ALERT | | F35: 10 | G35: 1 | H35: | VREF-TEMP | | I35: | ALERT | | J35: 10 | K35: 1 | L35: Hovering 140/139: v0.3.0 toggles every cycle; v1.0.0 stays in alert
A36: Temperature | B36: 14 | C36: Temperature pin 0.679 V (ADC 139) | D36: |5.0100V-T0.000A | | E36: |12.030VLE0.720A | | F36: 10 | G36: 0 | H36: | VREF-TEMP | | I36: | ALERT | | J36: 10 | K36: 0 | L36: Hovering 140/139: v0.3.0 toggles every cycle; v1.0.0 stays in alert
A37: Temperature | B37: 15 | C37: Temperature pin 0.684 V (ADC 140) | D37: | IC6-TEMP | | E37: | ALERT | | F37: 10 | G37: 1 | H37: | VREF-TEMP | | I37: | ALERT | | J37: 10 | K37: 0 | L37: Hovering 140/139: v0.3.0 toggles every cycle; v1.0.0 stays in alert
A38: Temperature | B38: 16 | C38: Temperature pin 0.679 V (ADC 139) | D38: |5.0100V-T0.000A | | E38: |12.030VLE0.720A | | F38: 10 | G38: 0 | H38: | VREF-TEMP | | I38: | ALERT | | J38: 10 | K38: 0 | L38: Hovering 140/139: v0.3.0 toggles every cycle; v1.0.0 stays in alert
A39: Temperature | B39: 17 | C39: Temperature pin 0.645 V (ADC 132) | D39: |5.0100V-T0.000A | | E39: |12.030VLE0.720A | | F39: 10 | G39: 0 | H39: | 5.020V 0.000A | | I39: |12.030V 0.720A | | J39: 10 | K39: 1
A40: Crosstalk | B40: 0 | C40: Model: first 0 read(s) after a channel switch return the previous channel value; CH1 17.70 V / 0.72 A | D40: |5.0100V-T0.000A | | E40: |17.700VLE0.720A | | F40: 10 | G40: 0 | H40: | 5.020V 0.000A | | I40: |17.700V 0.720A | | J40: 10 | K40: 0
A41: Crosstalk | B41: 1 | C41: Model: first 1 read(s) after a channel switch return the previous channel value; CH1 17.70 V / 0.72 A | D41: |5.0100V-T0.000A | | E41: |17.700VLE0.720A | | F41: 10 | G41: 0 | H41: | 5.020V 0.000A | | I41: |17.700V 0.720A | | J41: 10 | K41: 0
...

Sheet Findings
A1: Findings and observations for v1.0.0 (open and closed)
A2: Severity: Observation / Risk / Info / Cosmetic. None blocks the release; bench checks are in the Bench Test Plan.
A4: ID | B4: Severity | C4: Status | D4: Finding | E4: Details | F4: Evidence | G4: Action
A5: F-01 | B5: Observation | C5: Open - check on bench | D5: Outlier rejection trade-off | E5: v1.0.0 ignores samples more than 8 counts from the median. With 2% single-sample dropouts it shows 0.720 A in all 300 cycles; with rejection off (OUTLIER_LIMIT_COUNTS = 1023, a plain average) the display changed 215 times (0.65-0.72 A). v0.3.0 showed 0.02 A in 5 cycles. If the real signal has large asymmetric ripple (more than ±8 counts), the plain average is more accurate. | F5: Tests A-07 to A-09; Stability Tests sheet | G5: Keep 8 unless bench test BT-43 shows the plain average (1023) reads closer to the reference on the load that caused the oscillation.
A6: F-02 | B6: Observation | C6: Fixed in final file | D6: Display ran backwards at 0.800 V (closed) | E6: v0.3.0 and the first v1.0.0 build: step 0 (0.800 V) got no +0.030 V offset, so a rising input showed 0.790, 0.810, 0.800, 0.840. The final file replaces the offset bands with one calibration line, so the display always rises: 0.800, 0.810, 0.820 ... | F6: V-04, V-09, U-10; ramp RL; fine sweep | G6: None. BT-03 / BT-13 still check accuracy at 0.80 V.
A7: F-03 | B7: Observation | C7: Fixed in final file | D7: Calibration band edges (closed) | E7: The offset bands changed by 10-20 mV at 4.15, 5.98, 8.761, 13.01, 15.02 and 16.03 V, so the display could step back (4.170, 4.180, 4.170). The calibration line has no edges: 0 reversals in 40,922 ramp steps. | F7: V-05, V-09; ramp RV; fine sweep | G7: None. BT-04 / BT-14 still check accuracy at 4.15 V.
A8: F-04 | B8: Observation | C8: Open - recommendation | D8: No hysteresis on the OL limits | E8: With ±1 count of noise exactly at full scale, the display alternates between OL and 20.100/20.110V (voltage) or 5.000A and OL (current), about every other cycle. | F8: Tests E-03, E-04 | G8: Only at 20.1 V or 5.00 A, above the supply rating (0.8-20 V, 4 A), so only in a fault. Optional: add a small hysteresis to the OL decision.
A9: F-05 | B9: Observation | C9: Open - recommendation | D9: LEDs keep their last state during a temperature alert | E9: Measurements pause, so a LED may stay on (or off) until the alert ends. Same as v0.3.0. | F9: Test L-04 | G9: Optional: turn both LEDs off when the alert starts.
A10: F-06 | B10: Info | C10: Open - recommendation | D10: "WATCHDOG RESET" message may not appear on boards with Optiboot | E10: Optiboot clears MCUSR before the firmware starts, so the reset cause reads 0. The watchdog itself still works (verified). | F10: Test W-01 (no bootloader in simulation) | G10: Optional: also read the reset cause Optiboot leaves in register r2. Not implemented because it cannot be tested here.
A11: F-07 | B11: Risk | C11: Open - check on bench | D11: Old Nano bootloader and the watchdog | E11: Boards that only accept "ATmega328P (Old Bootloader)" do not disable the watchdog after a watchdog reset and can reset endlessly. | F11: Known ATmegaBOOT behavior | G11: Before flashing, check the board uploads with Processor "ATmega328P" (BT-01). Burn Optiboot otherwise.
A12: F-08 | B12: Info | C12: Open - check on bench | D12: Pull-ups on A4/A5 and D2/D4/D6 | E12: The firmware enables pull-ups on pins it does not use. | F12: Pin setup | G12: Confirm on the PCB that none of these pins is connected (BT-02).
A13: F-09 | B13: Info | C13: Open - recommendation | D13: fabs() promotes float to double | E13: Reported only with -Wdouble-promotion (lines 492, 533). On the ATmega328P double is the same 32-bit type as float, so results and speed are unchanged. | F13: Test B-06 | G13: No change needed; the Arduino IDE never enables this warning. fabsf() does not help: avr-libc defines it as fabs(). __builtin_fabsf() removes the warning with an identical binary (tested), but is less readable.
A14: F-10 | B14: Cosmetic | C14: Open - recommendation | D14: Two names for the current-sense voltage | E14: The MAX9919 output in mV is called currentSenseMv in computeCurrent() but voltageSenseMv in findNearestCurrentStep(), which receives it. "voltageSense" can also be confused with the voltage channel. | F14: Code review (lines 223, 501-515) | G14: Optional: rename the parameter of findNearestCurrentStep() to currentSenseMv (6 places). A name-only change: the compiled program does not change.
