Workbook

Sheet Summary
A1: Smart Fan Temperature Controller – firmware v1.0.0 production verification
A2: Compared against the previous firmware v0.2.1 (smart_fan_temperature_controller_fw_v0.2.1.ino, released January 2024). Target: ATmega328P @ 16 MHz.
A4: Firmware file | B4: smart_fan_temperature_controller_fw_v1.0.0.ino
A5: Reference firmware | B5: smart_fan_temperature_controller_fw_v0.2.1.ino (v0.2.1, released January 2024)
A6: Build – production (DEBUG_FLAG 0) | B6: 6,422 bytes flash (19.6 %), 216 bytes RAM (10.5 %) – avr-gcc, Arduino AVR core, no warnings
A7: Build – debug (DEBUG_FLAG 1) | B7: 8,280 bytes flash (25.3 %), 232 bytes RAM (11.3 %) – no warnings
A8: Verification method | B8: Both sketches were executed unmodified on a host PC with an Arduino/AVR emulation layer (registers, pins, ADC, FG interrupt, buzzer, serial). Only change for v0.2.1: its lookup array declared as int16_t so sizeof() matches the 2-byte AVR int. Values in gray cells are firmware outputs; white cells are Excel formulas cross-checking them.
A9: Not covered | B9: Analogue hardware (sensor accuracy, AREF stability, supply noise) and real fan behaviour – these require bench testing.
A11: Test sheet | B11: Cases | C11: Identical / OK | D11: Intended change | E11: Different / check | F11: Result
A12: Temp_to_PWM | B12: =COUNTA(Temp_to_PWM!A5:A475) -> 471 | C12: =COUNTIF(Temp_to_PWM!G5:G475,"Identical")+COUNTIF(Temp_to_PWM!G5:G475,"Both error") -> 460 | D12: =COUNTIF(Temp_to_PWM!G5:G475,"Fixed*") -> 10 | E12: =COUNTIF(Temp_to_PWM!G5:G475,"Different") -> 1 | F12: Only difference: exact 5.000 °C (unreachable from sensors). All v1.0.0 values match the formula.
A13: Sensor_Inputs | B13: =COUNTA(Sensor_Inputs!B5:B21) -> 17 | C13: =COUNTIF(Sensor_Inputs!O5:O21,"Identical")+COUNTIF(Sensor_Inputs!O5:O21,"Both error") -> 14 | D13: =COUNTIF(Sensor_Inputs!O5:O21,"Fixed*")+COUNTIF(Sensor_Inputs!O5:O21,"New:*") -> 3 | E13: =COUNTIF(Sensor_Inputs!O5:O21,"Different") -> 0 | F13: Differences are the dead-zone fix and the new divergence detection.
A14: LED_Alarm_Matrix | B14: =COUNTA(LED_Alarm_Matrix!B5:B32) -> 28 | C14: =COUNTIF(LED_Alarm_Matrix!O5:O32,"Same") -> 14 | D14: =COUNTIF(LED_Alarm_Matrix!O5:O32,"Changed*") -> 14 | E14: 0 | F14: Changes = D6 for failed fan test, sustained-max alarm, divergence LED.
A15: Fan_Startup_Test | B15: =COUNTA(Fan_Startup_Test!A5:A20) -> 16 | C15: =COUNTIF(Fan_Startup_Test!G5:G20,"Identical") -> 16 | D15: 0 | E15: =COUNTIF(Fan_Startup_Test!F5:F20,"CHECK")+COUNTIF(Fan_Startup_Test!G5:G20,"Different") -> 0 | F15: Same pass window (53–56 pulses) as v0.2.1.
A16: ADC_Sweep | B16: =ADC_Sweep!B11 -> 1048576 | C16: =ADC_Sweep!B5+ADC_Sweep!B6 -> 1002064 | D16: =ADC_Sweep!B8+ADC_Sweep!B9 -> 46512 | E16: =ADC_Sweep!B7+ADC_Sweep!B10 -> 0 | F16: =ADC_Sweep!B13 -> Match: identical to v0.2.1 for every valid reading
A17: Sequences | B17: 48 | C17: – | D17: – | E17: – | F17: 8 time sequences incl. over-temperature, sensor failure, fan stall, divergence, known limitation
A18: Watchdog_Timing | B18: 2 | C18: =COUNTIF(Watchdog_Timing!B22:C22,"OK") -> 2 | D18: 0 | E18: =COUNTIF(Watchdog_Timing!B22:C22,"CHECK") -> 0 | F18: Worst-case loop well below 8 s in production and debug.
A20: Verdict
A21: v1.0.0 regulates the fan exactly like v0.2.1 for every real sensor reading, fixes the 26–27 °C dead zone, and adds sensor-divergence detection, sustained-max-PWM alarm and watchdog protection. Remaining open items are cosmetic comments only (see Corrections_Log). Firmware is ready for production; confirm with bench tests on the target hardware.
A23: Legend
A24: Blue text | B24: Test input / stimulus or firmware constant
A25: Gray fill | B25: Value produced by running the firmware
A26: White, black text | B26: Excel formula (cross-check)
A27: Yellow header | B27: v0.2.1 firmware columns (previous firmware)
A28: Green | B28: Identical / OK
A29: Amber | B29: Intended change or fix
A30: Red | B30: Unexpected difference (none remaining)

Sheet Constants
A1: Firmware constants used by the checks
A2: Blue = values copied from smart_fan_temperature_controller_fw_v1.0.0.ino (line numbers in column E). Every formula in this workbook references these cells.
A4: Constant | B4: Value | C4: Unit | D4: Meaning | E4: Source
A5: PWM_TOP | B5: 320 | C5: counts | D5: Timer1 TOP (ICR1) – 100 % duty | E5: v1.0.0 line 53
A6: PWM_AT_MINIMUM_TEMPERATURE | B6: 5 | C6: counts | D6: PWM at 5 °C | E6: line 55
A7: PWM_STEP_PER_DEGREE | B7: 7 | C7: counts/°C | D7: PWM increase per °C | E7: line 58
A8: CELSIUS_MINIMUM_TEMPERATURE | B8: 5 | C8: °C | D8: Lower valid temperature (inclusive) | E8: line 37
A9: CELSIUS_MAXIMUM_TEMPERATURE | B9: 50 | C9: °C | D9: Upper valid temperature (inclusive) | E9: line 38
A10: MAX_SENSOR_DIVERGENCE_CELSIUS | B10: 5 | C10: °C | D10: Max allowed difference LM35 vs LM34 (strictly greater = error) | E10: line 44
A11: TEMPERATURE_PWM_ERROR | B11: -1 | C11: code | D11: v1.0.0 code: temperature out of range | E11: line 61
A12: TEMPERATURE_DIVERGENCE_ERROR | B12: -2 | C12: code | D12: v1.0.0 code: sensors disagree | E12: line 64
A13: v0.2.1 error sentinel | B13: 15797 | C13: code | D13: v0.2.1 code: out of range / not found | E13: v0.2.1 temperatureToPwm()
A14: FAN_TEST_MINIMUM_PULSES | B14: 52 | C14: pulses | D14: Fan test passes if pulses > this value | E14: line 71
A15: FAN_TEST_MAXIMUM_PULSES | B15: 57 | C15: pulses | D15: Fan test passes if pulses < this value | E15: line 72
A16: FAN_TEST_PWM | B16: 128 | C16: counts | D16: PWM during fan test (40 % duty) | E16: line 69
... A30: RPM per FG pulse per second | B30: 30 | C30: rpm | D30: 2 FG pulses per revolution → pulses/s × 60 / 2 | E30: line 118 comment

Sheet Temp_to_PWM
A1: Temperature → fan PWM, every 0.1 °C from 4.0 to 51.0 °C
A2: Function-level test: the average temperature is passed directly to temperatureToPWM() (v1.0.0) and temperatureToPwm() (v0.2.1). Gray = firmware output, white = Excel cross-check formula.
A4: Avg temp °C | B4: v0.2.1 PWM | C4: v1.0.0 PWM | D4: Expected v1.0.0 (formula) | E4: v1.0.0 vs formula | F4: v1.0.0 duty % | G4: v1.0.0 vs v0.2.1 | H4: Note
A5: 4 | B5: 15797 | C5: -1 | D5: =IF(AND(A5>=Constants!$B$8,A5<=Constants!$B$9),Constants!$B$6+Constants!$B$7*(CEILING(A5,1)-Constants!$B$8),Constants!$B$11) -> -1 | E5: =IF(C5=D5,"OK","CHECK") -> OK | F5: =IF(C5>=0,C5/Constants!$B$5,"n/a") -> n/a | G5: =IF(AND(B5=Constants!$B$13,C5<0),"Both error",IF(B5=C5,"Identical",IF(AND(B5=Constants!$B$13,C5>=0),"Fixed in v1.0.0","Different"))) -> Both error | H5: Out of range: fan keeps last good PWM, board LED D4 ON
A6: 4.1 | B6: 15797 | C6: -1 | D6: =IF(AND(A6>=Constants!$B$8,A6<=Constants!$B$9),Constants!$B$6+Constants!$B$7*(CEILING(A6,1)-Constants!$B$8),Constants!$B$11) -> -1 | E6: =IF(C6=D6,"OK","CHECK") -> OK | F6: =IF(C6>=0,C6/Constants!$B$5,"n/a") -> n/a | G6: =IF(AND(B6=Constants!$B$13,C6<0),"Both error",IF(B6=C6,"Identical",IF(AND(B6=Constants!$B$13,C6>=0),"Fixed in v1.0.0","Different"))) -> Both error | H6: Out of range: fan keeps last good PWM, board LED D4 ON
A7: 4.2 | B7: 15797 | C7: -1 | D7: =IF(AND(A7>=Constants!$B$8,A7<=Constants!$B$9),Constants!$B$6+Constants!$B$7*(CEILING(A7,1)-Constants!$B$8),Constants!$B$11) -> -1 | E7: =IF(C7=D7,"OK","CHECK") -> OK | F7: =IF(C7>=0,C7/Constants!$B$5,"n/a") -> n/a | G7: =IF(AND(B7=Constants!$B$13,C7<0),"Both error",IF(B7=C7,"Identical",IF(AND(B7=Constants!$B$13,C7>=0),"Fixed in v1.0.0","Different"))) -> Both error | H7: Out of range: fan keeps last good PWM, board LED D4 ON
A8: 4.3 | B8: 15797 | C8: -1 | D8: =IF(AND(A8>=Constants!$B$8,A8<=Constants!$B$9),Constants!$B$6+Constants!$B$7*(CEILING(A8,1)-Constants!$B$8),Constants!$B$11) -> -1 | E8: =IF(C8=D8,"OK","CHECK") -> OK | F8: =IF(C8>=0,C8/Constants!$B$5,"n/a") -> n/a | G8: =IF(AND(B8=Constants!$B$13,C8<0),"Both error",IF(B8=C8,"Identical",IF(AND(B8=Constants!$B$13,C8>=0),"Fixed in v1.0.0","Different"))) -> Both error | H8: Out of range: fan keeps last good PWM, board LED D4 ON
A9: 4.4 | B9: 15797 | C9: -1 | D9: =IF(AND(A9>=Constants!$B$8,A9<=Constants!$B$9),Constants!$B$6+Constants!$B$7*(CEILING(A9,1)-Constants!$B$8),Constants!$B$11) -> -1 | E9: =IF(C9=D9,"OK","CHECK") -> OK | F9: =IF(C9>=0,C9/Constants!$B$5,"n/a") -> n/a | G9: =IF(AND(B9=Constants!$B$13,C9<0),"Both error",IF(B9=C9,"Identical",IF(AND(B9=Constants!$B$13,C9>=0),"Fixed in v1.0.0","Different"))) -> Both error | H9: Out of range: fan keeps last good PWM, board LED D4 ON
A10: 4.5 | B10: 15797 | C10: -1 | D10: =IF(AND(A10>=Constants!$B$8,A10<=Constants!$B$9),Constants!$B$6+Constants!$B$7*(CEILING(A10,1)-Constants!$B$8),Constants!$B$11) -> -1 | E10: =IF(C10=D10,"OK","CHECK") -> OK | F10: =IF(C10>=0,C10/Constants!$B$5,"n/a") -> n/a | G10: =IF(AND(B10=Constants!$B$13,C10<0),"Both error",IF(B10=C10,"Identical",IF(AND(B10=Constants!$B$13,C10>=0),"Fixed in v1.0.0","Different"))) -> Both error | H10: Out of range: fan keeps last good PWM, board LED D4 ON
A11: 4.6 | B11: 15797 | C11: -1 | D11: =IF(AND(A11>=Constants!$B$8,A11<=Constants!$B$9),Constants!$B$6+Constants!$B$7*(CEILING(A11,1)-Constants!$B$8),Constants!$B$11) -> -1 | E11: =IF(C11=D11,"OK","CHECK") -> OK | F11: =IF(C11>=0,C11/Constants!$B$5,"n/a") -> n/a | G11: =IF(AND(B11=Constants!$B$13,C11<0),"Both error",IF(B11=C11,"Identical",IF(AND(B11=Constants!$B$13,C11>=0),"Fixed in v1.0.0","Different"))) -> Both error | H11: Out of range: fan keeps last good PWM, board LED D4 ON
A12: 4.7 | B12: 15797 | C12: -1 | D12: =IF(AND(A12>=Constants!$B$8,A12<=Constants!$B$9),Constants!$B$6+Constants!$B$7*(CEILING(A12,1)-Constants!$B$8),Constants!$B$11) -> -1 | E12: =IF(C12=D12,"OK","CHECK") -> OK | F12: =IF(C12>=0,C12/Constants!$B$5,"n/a") -> n/a | G12: =IF(AND(B12=Constants!$B$13,C12<0),"Both error",IF(B12=C12,"Identical",IF(AND(B12=Constants!$B$13,C12>=0),"Fixed in v1.0.0","Different"))) -> Both error | H12: Out of range: fan keeps last good PWM, board LED D4 ON
A13: 4.8 | B13: 15797 | C13: -1 | D13: =IF(AND(A13>=Constants!$B$8,A13<=Constants!$B$9),Constants!$B$6+Constants!$B$7*(CEILING(A13,1)-Constants!$B$8),Constants!$B$11) -> -1 | E13: =IF(C13=D13,"OK","CHECK") -> OK | F13: =IF(C13>=0,C13/Constants!$B$5,"n/a") -> n/a | G13: =IF(AND(B13=Constants!$B$13,C13<0),"Both error",IF(B13=C13,"Identical",IF(AND(B13=Constants!$B$13,C13>=0),"Fixed in v1.0.0","Different"))) -> Both error | H13: Out of range: fan keeps last good PWM, board LED D4 ON
A14: 4.9 | B14: 15797 | C14: -1 | D14: =IF(AND(A14>=Constants!$B$8,A14<=Constants!$B$9),Constants!$B$6+Constants!$B$7*(CEILING(A14,1)-Constants!$B$8),Constants!$B$11) -> -1 | E14: =IF(C14=D14,"OK","CHECK") -> OK | F14: =IF(C14>=0,C14/Constants!$B$5,"n/a") -> n/a | G14: =IF(AND(B14=Constants!$B$13,C14<0),"Both error",IF(B14=C14,"Identical",IF(AND(B14=Constants!$B$13,C14>=0),"Fixed in v1.0.0","Different"))) -> Both error | H14: Out of range: fan keeps last good PWM, board LED D4 ON
A15: 5 | B15: 12 | C15: 5 | D15: =IF(AND(A15>=Constants!$B$8,A15<=Constants!$B$9),Constants!$B$6+Constants!$B$7*(CEILING(A15,1)-Constants!$B$8),Constants!$B$11) -> 5 | E15: =IF(C15=D15,"OK","CHECK") -> OK | F15: =IF(C15>=0,C15/Constants!$B$5,"n/a") -> 0.015625 | G15: =IF(AND(B15=Constants!$B$13,C15<0),"Both error",IF(B15=C15,"Identical",IF(AND(B15=Constants!$B$13,C15>=0),"Fixed in v1.0.0","Different"))) -> Different | H15: Exactly 5.000 °C only: v0.2.1 gives 12. Not reachable from real sensor readings (ADC quantisation) – confirmed in ADC_Sweep
A16: 5.1 | B16: 12 | C16: 12 | D16: =IF(AND(A16>=Constants!$B$8,A16<=Constants!$B$9),Constants!$B$6+Constants!$B$7*(CEILING(A16,1)-Constants!$B$8),Constants!$B$11) -> 12 | E16: =IF(C16=D16,"OK","CHECK") -> OK | F16: =IF(C16>=0,C16/Constants!$B$5,"n/a") -> 0.0375 | G16: =IF(AND(B16=Constants!$B$13,C16<0),"Both error",IF(B16=C16,"Identical",IF(AND(B16=Constants!$B$13,C16>=0),"Fixed in v1.0.0","Different"))) -> Identical
A17: 5.2 | B17: 12 | C17: 12 | D17: =IF(AND(A17>=Constants!$B$8,A17<=Constants!$B$9),Constants!$B$6+Constants!$B$7*(CEILING(A17,1)-Constants!$B$8),Constants!$B$11) -> 12 | E17: =IF(C17=D17,"OK","CHECK") -> OK | F17: =IF(C17>=0,C17/Constants!$B$5,"n/a") -> 0.0375 | G17: =IF(AND(B17=Constants!$B$13,C17<0),"Both error",IF(B17=C17,"Identical",IF(AND(B17=Constants!$B$13,C17>=0),"Fixed in v1.0.0","Different"))) -> Identical
A18: 5.3 | B18: 12 | C18: 12 | D18: =IF(AND(A18>=Constants!$B$8,A18<=Constants!$B$9),Constants!$B$6+Constants!$B$7*(CEILING(A18,1)-Constants!$B$8),Constants!$B$11) -> 12 | E18: =IF(C18=D18,"OK","CHECK") -> OK | F18: =IF(C18>=0,C18/Constants!$B$5,"n/a") -> 0.0375 | G18: =IF(AND(B18=Constants!$B$13,C18<0),"Both error",IF(B18=C18,"Identical",IF(AND(B18=Constants!$B$13,C18>=0),"Fixed in v1.0.0","Different"))) -> Identical
A19: 5.4 | B19: 12 | C19: 12 | D19: =IF(AND(A19>=Constants!$B$8,A19<=Constants!$B$9),Constants!$B$6+Constants!$B$7*(CEILING(A19,1)-Constants!$B$8),Constants!$B$11) -> 12 | E19: =IF(C19=D19,"OK","CHECK") -> OK | F19: =IF(C19>=0,C19/Constants!$B$5,"n/a") -> 0.0375 | G19: =IF(AND(B19=Constants!$B$13,C19<0),"Both error",IF(B19=C19,"Identical",IF(AND(B19=Constants!$B$13,C19>=0),"Fixed in v1.0.0","Different"))) -> Identical
A20: 5.5 | B20: 12 | C20: 12 | D20: =IF(AND(A20>=Constants!$B$8,A20<=Constants!$B$9),Constants!$B$6+Constants!$B$7*(CEILING(A20,1)-Constants!$B$8),Constants!$B$11) -> 12 | E20: =IF(C20=D20,"OK","CHECK") -> OK | F20: =IF(C20>=0,C20/Constants!$B$5,"n/a") -> 0.0375 | G20: =IF(AND(B20=Constants!$B$13,C20<0),"Both error",IF(B20=C20,"Identical",IF(AND(B20=Constants!$B$13,C20>=0),"Fixed in v1.0.0","Different"))) -> Identical
A21: 5.6 | B21: 12 | C21: 12 | D21: =IF(AND(A21>=Constants!$B$8,A21<=Constants!$B$9),Constants!$B$6+Constants!$B$7*(CEILING(A21,1)-Constants!$B$8),Constants!$B$11) -> 12 | E21: =IF(C21=D21,"OK","CHECK") -> OK | F21: =IF(C21>=0,C21/Constants!$B$5,"n/a") -> 0.0375 | G21: =IF(AND(B21=Constants!$B$13,C21<0),"Both error",IF(B21=C21,"Identical",IF(AND(B21=Constants!$B$13,C21>=0),"Fixed in v1.0.0","Different"))) -> Identical
A22: 5.7 | B22: 12 | C22: 12 | D22: =IF(AND(A22>=Constants!$B$8,A22<=Constants!$B$9),Constants!$B$6+Constants!$B$7*(CEILING(A22,1)-Constants!$B$8),Constants!$B$11) -> 12 | E22: =IF(C22=D22,"OK","CHECK") -> OK | F22: =IF(C22>=0,C22/Constants!$B$5,"n/a") -> 0.0375 | G22: =IF(AND(B22=Constants!$B$13,C22<0),"Both error",IF(B22=C22,"Identical",IF(AND(B22=Constants!$B$13,C22>=0),"Fixed in v1.0.0","Different"))) -> Identical
A23: 5.8 | B23: 12 | C23: 12 | D23: =IF(AND(A23>=Constants!$B$8,A23<=Constants!$B$9),Constants!$B$6+Constants!$B$7*(CEILING(A23,1)-Constants!$B$8),Constants!$B$11) -> 12 | E23: =IF(C23=D23,"OK","CHECK") -> OK | F23: =IF(C23>=0,C23/Constants!$B$5,"n/a") -> 0.0375 | G23: =IF(AND(B23=Constants!$B$13,C23<0),"Both error",IF(B23=C23,"Identical",IF(AND(B23=Constants!$B$13,C23>=0),"Fixed in v1.0.0","Different"))) -> Identical
A24: 5.9 | B24: 12 | C24: 12 | D24: =IF(AND(A24>=Constants!$B$8,A24<=Constants!$B$9),Constants!$B$6+Constants!$B$7*(CEILING(A24,1)-Constants!$B$8),Constants!$B$11) -> 12 | E24: =IF(C24=D24,"OK","CHECK") -> OK | F24: =IF(C24>=0,C24/Constants!$B$5,"n/a") -> 0.0375 | G24: =IF(AND(B24=Constants!$B$13,C24<0),"Both error",IF(B24=C24,"Identical",IF(AND(B24=Constants!$B$13,C24>=0),"Fixed in v1.0.0","Different"))) -> Identical
A25: 6 | B25: 12 | C25: 12 | D25: =IF(AND(A25>=Constants!$B$8,A25<=Constants!$B$9),Constants!$B$6+Constants!$B$7*(CEILING(A25,1)-Constants!$B$8),Constants!$B$11) -> 12 | E25: =IF(C25=D25,"OK","CHECK") -> OK | F25: =IF(C25>=0,C25/Constants!$B$5,"n/a") -> 0.0375 | G25: =IF(AND(B25=Constants!$B$13,C25<0),"Both error",IF(B25=C25,"Identical",IF(AND(B25=Constants!$B$13,C25>=0),"Fixed in v1.0.0","Different"))) -> Identical
A26: 6.1 | B26: 19 | C26: 19 | D26: =IF(AND(A26>=Constants!$B$8,A26<=Constants!$B$9),Constants!$B$6+Constants!$B$7*(CEILING(A26,1)-Constants!$B$8),Constants!$B$11) -> 19 | E26: =IF(C26=D26,"OK","CHECK") -> OK | F26: =IF(C26>=0,C26/Constants!$B$5,"n/a") -> 0.059375 | G26: =IF(AND(B26=Constants!$B$13,C26<0),"Both error",IF(B26=C26,"Identical",IF(AND(B26=Constants!$B$13,C26>=0),"Fixed in v1.0.0","Different"))) -> Identical
A27: 6.2 | B27: 19 | C27: 19 | D27: =IF(AND(A27>=Constants!$B$8,A27<=Constants!$B$9),Constants!$B$6+Constants!$B$7*(CEILING(A27,1)-Constants!$B$8),Constants!$B$11) -> 19 | E27: =IF(C27=D27,"OK","CHECK") -> OK | F27: =IF(C27>=0,C27/Constants!$B$5,"n/a") -> 0.059375 | G27: =IF(AND(B27=Constants!$B$13,C27<0),"Both error",IF(B27=C27,"Identical",IF(AND(B27=Constants!$B$13,C27>=0),"Fixed in v1.0.0","Different"))) -> Identical
... A225: 26 | B225: 152 | C225: 152 | D225: =IF(AND(A225>=Constants!$B$8,A225<=Constants!$B$9),Constants!$B$6+Constants!$B$7*(CEILING(A225,1)-Constants!$B$8),Constants!$B$11) -> 152 | E225: =IF(C225=D225,"OK","CHECK") -> OK | F225: =IF(C225>=0,C225/Constants!$B$5,"n/a") -> 0.475 | G225: =IF(AND(B225=Constants!$B$13,C225<0),"Both error",IF(B225=C225,"Identical",IF(AND(B225=Constants!$B$13,C225>=0),"Fixed in v1.0.0","Different"))) -> Identical
A226: 26.1 | B226: 15797 | C226: 159 | D226: =IF(AND(A226>=Constants!$B$8,A226<=Constants!$B$9),Constants!$B$6+Constants!$B$7*(CEILING(A226,1)-Constants!$B$8),Constants!$B$11) -> 159 | E226: =IF(C226=D226,"OK","CHECK") -> OK | F226: =IF(C226>=0,C226/Constants!$B$5,"n/a") -> 0.496875 | G226: =IF(AND(B226=Constants!$B$13,C226<0),"Both error",IF(B226=C226,"Identical",IF(AND(B226=Constants!$B$13,C226>=0),"Fixed in v1.0.0","Different"))) -> Fixed in v1.0.0 | H226: v0.2.1 26–27 °C dead-zone bug (returned error for a valid temperature)
A227: 26.2 | B227: 15797 | C227: 159 | D227: =IF(AND(A227>=Constants!$B$8,A227<=Constants!$B$9),Constants!$B$6+Constants!$B$7*(CEILING(A227,1)-Constants!$B$8),Constants!$B$11) -> 159 | E227: =IF(C227=D227,"OK","CHECK") -> OK | F227: =IF(C227>=0,C227/Constants!$B$5,"n/a") -> 0.496875 | G227: =IF(AND(B227=Constants!$B$13,C227<0),"Both error",IF(B227=C227,"Identical",IF(AND(B227=Constants!$B$13,C227>=0),"Fixed in v1.0.0","Different"))) -> Fixed in v1.0.0 | H227: v0.2.1 26–27 °C dead-zone bug (returned error for a valid temperature)
A228: 26.3 | B228: 15797 | C228: 159 | D228: =IF(AND(A228>=Constants!$B$8,A228<=Constants!$B$9),Constants!$B$6+Constants!$B$7*(CEILING(A228,1)-Constants!$B$8),Constants!$B$11) -> 159 | E228: =IF(C228=D228,"OK","CHECK") -> OK | F228: =IF(C228>=0,C228/Constants!$B$5,"n/a") -> 0.496875 | G228: =IF(AND(B228=Constants!$B$13,C228<0),"Both error",IF(B228=C228,"Identical",IF(AND(B228=Constants!$B$13,C228>=0),"Fixed in v1.0.0","Different"))) -> Fixed in v1.0.0 | H228: v0.2.1 26–27 °C dead-zone bug (returned error for a valid temperature)
A229: 26.4 | B229: 15797 | C229: 159 | D229: =IF(AND(A229>=Constants!$B$8,A229<=Constants!$B$9),Constants!$B$6+Constants!$B$7*(CEILING(A229,1)-Constants!$B$8),Constants!$B$11) -> 159 | E229: =IF(C229=D229,"OK","CHECK") -> OK | F229: =IF(C229>=0,C229/Constants!$B$5,"n/a") -> 0.496875 | G229: =IF(AND(B229=Constants!$B$13,C229<0),"Both error",IF(B229=C229,"Identical",IF(AND(B229=Constants!$B$13,C229>=0),"Fixed in v1.0.0","Different"))) -> Fixed in v1.0.0 | H229: v0.2.1 26–27 °C dead-zone bug (returned error for a valid temperature)
A230: 26.5 | B230: 15797 | C230: 159 | D230: =IF(AND(A230>=Constants!$B$8,A230<=Constants!$B$9),Constants!$B$6+Constants!$B$7*(CEILING(A230,1)-Constants!$B$8),Constants!$B$11) -> 159 | E230: =IF(C230=D230,"OK","CHECK") -> OK | F230: =IF(C230>=0,C230/Constants!$B$5,"n/a") -> 0.496875 | G230: =IF(AND(B230=Constants!$B$13,C230<0),"Both error",IF(B230=C230,"Identical",IF(AND(B230=Constants!$B$13,C230>=0),"Fixed in v1.0.0","Different"))) -> Fixed in v1.0.0 | H230: v0.2.1 26–27 °C dead-zone bug (returned error for a valid temperature)
A231: 26.6 | B231: 15797 | C231: 159 | D231: =IF(AND(A231>=Constants!$B$8,A231<=Constants!$B$9),Constants!$B$6+Constants!$B$7*(CEILING(A231,1)-Constants!$B$8),Constants!$B$11) -> 159 | E231: =IF(C231=D231,"OK","CHECK") -> OK | F231: =IF(C231>=0,C231/Constants!$B$5,"n/a") -> 0.496875 | G231: =IF(AND(B231=Constants!$B$13,C231<0),"Both error",IF(B231=C231,"Identical",IF(AND(B231=Constants!$B$13,C231>=0),"Fixed in v1.0.0","Different"))) -> Fixed in v1.0.0 | H231: v0.2.1 26–27 °C dead-zone bug (returned error for a valid temperature)
A232: 26.7 | B232: 15797 | C232: 159 | D232: =IF(AND(A232>=Constants!$B$8,A232<=Constants!$B$9),Constants!$B$6+Constants!$B$7*(CEILING(A232,1)-Constants!$B$8),Constants!$B$11) -> 159 | E232: =IF(C232=D232,"OK","CHECK") -> OK | F232: =IF(C232>=0,C232/Constants!$B$5,"n/a") -> 0.496875 | G232: =IF(AND(B232=Constants!$B$13,C232<0),"Both error",IF(B232=C232,"Identical",IF(AND(B232=Constants!$B$13,C232>=0),"Fixed in v1.0.0","Different"))) -> Fixed in v1.0.0 | H232: v0.2.1 26–27 °C dead-zone bug (returned error for a valid temperature)
A233: 26.8 | B233: 15797 | C233: 159 | D233: =IF(AND(A233>=Constants!$B$8,A233<=Constants!$B$9),Constants!$B$6+Constants!$B$7*(CEILING(A233,1)-Constants!$B$8),Constants!$B$11) -> 159 | E233: =IF(C233=D233,"OK","CHECK") -> OK | F233: =IF(C233>=0,C233/Constants!$B$5,"n/a") -> 0.496875 | G233: =IF(AND(B233=Constants!$B$13,C233<0),"Both error",IF(B233=C233,"Identical",IF(AND(B233=Constants!$B$13,C233>=0),"Fixed in v1.0.0","Different"))) -> Fixed in v1.0.0 | H233: v0.2.1 26–27 °C dead-zone bug (returned error for a valid temperature)
A234: 26.9 | B234: 15797 | C234: 159 | D234: =IF(AND(A234>=Constants!$B$8,A234<=Constants!$B$9),Constants!$B$6+Constants!$B$7*(CEILING(A234,1)-Constants!$B$8),Constants!$B$11) -> 159 | E234: =IF(C234=D234,"OK","CHECK") -> OK | F234: =IF(C234>=0,C234/Constants!$B$5,"n/a") -> 0.496875 | G234: =IF(AND(B234=Constants!$B$13,C234<0),"Both error",IF(B234=C234,"Identical",IF(AND(B234=Constants!$B$13,C234>=0),"Fixed in v1.0.0","Different"))) -> Fixed in v1.0.0 | H234: v0.2.1 26–27 °C dead-zone bug (returned error for a valid temperature)
A235: 27 | B235: 15797 | C235: 159 | D235: =IF(AND(A235>=Constants!$B$8,A235<=Constants!$B$9),Constants!$B$6+Constants!$B$7*(CEILING(A235,1)-Constants!$B$8),Constants!$B$11) -> 159 | E235: =IF(C235=D235,"OK","CHECK") -> OK | F235: =IF(C235>=0,C235/Constants!$B$5,"n/a") -> 0.496875 | G235: =IF(AND(B235=Constants!$B$13,C235<0),"Both error",IF(B235=C235,"Identical",IF(AND(B235=Constants!$B$13,C235>=0),"Fixed in v1.0.0","Different"))) -> Fixed in v1.0.0 | H235: v0.2.1 26–27 °C dead-zone bug (returned error for a valid temperature)
A236: 27.1 | B236: 166 | C236: 166 | D236: =IF(AND(A236>=Constants!$B$8,A236<=Constants!$B$9),Constants!$B$6+Constants!$B$7*(CEILING(A236,1)-Constants!$B$8),Constants!$B$11) -> 166 | E236: =IF(C236=D236,"OK","CHECK") -> OK | F236: =IF(C236>=0,C236/Constants!$B$5,"n/a") -> 0.51875 | G236: =IF(AND(B236=Constants!$B$13,C236<0),"Both error",IF(B236=C236,"Identical",IF(AND(B236=Constants!$B$13,C236>=0),"Fixed in v1.0.0","Different"))) -> Identical
A237: 27.2 | B237: 166 | C237: 166 | D237: =IF(AND(A237>=Constants!$B$8,A237<=Constants!$B$9),Constants!$B$6+Constants!$B$7*(CEILING(A237,1)-Constants!$B$8),Constants!$B$11) -> 166 | E237: =IF(C237=D237,"OK","CHECK") -> OK | F237: =IF(C237>=0,C237/Constants!$B$5,"n/a") -> 0.51875 | G237: =IF(AND(B237=Constants!$B$13,C237<0),"Both error",IF(B237=C237,"Identical",IF(AND(B237=Constants!$B$13,C237>=0),"Fixed in v1.0.0","Different"))) -> Identical
A238: 27.3 | B238: 166 | C238: 166 | D238: =IF(AND(A238>=Constants!$B$8,A238<=Constants!$B$9),Constants!$B$6+Constants!$B$7*(CEILING(A238,1)-Constants!$B$8),Constants!$B$11) -> 166 | E238: =IF(C238=D238,"OK","CHECK") -> OK | F238: =IF(C238>=0,C238/Constants!$B$5,"n/a") -> 0.51875 | G238: =IF(AND(B238=Constants!$B$13,C238<0),"Both error",IF(B238=C238,"Identical",IF(AND(B238=Constants!$B$13,C238>=0),"Fixed in v1.0.0","Different"))) -> Identical
...

Sheet Sensor_Inputs
A1: Sensor input cases (raw ADC values → temperature → PWM)
A2: Both firmwares run calculateAverageTemperatureFromSensors()/temperatureFromSensors() and the PWM mapping on the same ADC counts.
A4: # | B4: Case | C4: ADC A0 (LM35) | D4: ADC A1 (LM34) | E4: LM35 °C (formula) | F4: LM34 °F (formula) | G4: LM34 as °C (formula) | H4: |LM35 − LM34| °C | I4: Divergence > limit? | J4: v0.2.1 avg °C | K4: v0.2.1 PWM | L4: v1.0.0 avg / sentinel | M4: v1.0.0 PWM code | N4: v1.0.0 result | O4: v1.0.0 vs v0.2.1 | P4: v1.0.0 fan behaviour
A5: 1 | B5: Normal 25 °C, sensors agree | C5: 103 | D5: 316 | E5: =C5/Constants!$B$27/Constants!$B$28 -> 25.103583 | F5: =D5/Constants!$B$27/Constants!$B$28 -> 77.016817 | G5: =(F5-32)*Constants!$B$29 -> 25.006842 | H5: =ABS(E5-G5) -> 0.096740921 | I5: =IF(AND(E5>=Constants!$B$8,E5<=Constants!$B$9,G5>=Constants!$B$8,G5<=Constants!$B$9),IF(H5>Constants!$B$10,"YES","no"),"n/a (out of range)") -> no | J5: 25.06 | K5: 152 | L5: 25.06 | M5: 152 | N5: =IF(M5=Constants!$B$12,"Sensor divergence",IF(M5=Constants!$B$11,"Out of range","Valid")) -> Valid | O5: =IF(AND(K5=Constants!$B$13,M5<0),"Both error",IF(K5=M5,"Identical",IF(AND(K5=Constants!$B$13,M5>=0),"Fixed in v1.0.0",IF(M5=Constants!$B$12,"New: divergence detected","Different")))) -> Identical | P5: =IF(M5<0,"Holds last good PWM, D4 ON","OCR1A = "&M5&" ("&TEXT(M5/Constants!$B$5,"0.0%")&")") -> OCR1A = 152 (48%)
A6: 2 | B6: Normal 30 °C, sensors agree | C6: 123 | D6: 353 | E6: =C6/Constants!$B$27/Constants!$B$28 -> 29.978065 | F6: =D6/Constants!$B$27/Constants!$B$28 -> 86.034609 | G6: =(F6-32)*Constants!$B$29 -> 30.016225 | H6: =ABS(E6-G6) -> 0.03816037 | I6: =IF(AND(E6>=Constants!$B$8,E6<=Constants!$B$9,G6>=Constants!$B$8,G6<=Constants!$B$9),IF(H6>Constants!$B$10,"YES","no"),"n/a (out of range)") -> no | J6: 30 | K6: 180 | L6: 30 | M6: 180 | N6: =IF(M6=Constants!$B$12,"Sensor divergence",IF(M6=Constants!$B$11,"Out of range","Valid")) -> Valid | O6: =IF(AND(K6=Constants!$B$13,M6<0),"Both error",IF(K6=M6,"Identical",IF(AND(K6=Constants!$B$13,M6>=0),"Fixed in v1.0.0",IF(M6=Constants!$B$12,"New: divergence detected","Different")))) -> Identical | P6: =IF(M6<0,"Holds last good PWM, D4 ON","OCR1A = "&M6&" ("&TEXT(M6/Constants!$B$5,"0.0%")&")") -> OCR1A = 180 (56%)
A7: 3 | B7: Normal 45 °C, sensors agree | C7: 185 | D7: 464 | E7: =C7/Constants!$B$27/Constants!$B$28 -> 45.088959 | F7: =D7/Constants!$B$27/Constants!$B$28 -> 113.08798 | G7: =(F7-32)*Constants!$B$29 -> 45.044375 | H7: =ABS(E7-G7) -> 0.044583963 | I7: =IF(AND(E7>=Constants!$B$8,E7<=Constants!$B$9,G7>=Constants!$B$8,G7<=Constants!$B$9),IF(H7>Constants!$B$10,"YES","no"),"n/a (out of range)") -> no | J7: 45.07 | K7: 292 | L7: 45.07 | M7: 292 | N7: =IF(M7=Constants!$B$12,"Sensor divergence",IF(M7=Constants!$B$11,"Out of range","Valid")) -> Valid | O7: =IF(AND(K7=Constants!$B$13,M7<0),"Both error",IF(K7=M7,"Identical",IF(AND(K7=Constants!$B$13,M7>=0),"Fixed in v1.0.0",IF(M7=Constants!$B$12,"New: divergence detected","Different")))) -> Identical | P7: =IF(M7<0,"Holds last good PWM, D4 ON","OCR1A = "&M7&" ("&TEXT(M7/Constants!$B$5,"0.0%")&")") -> OCR1A = 292 (91%)
A8: 4 | B8: Lower valid edge (~5.2 °C) | C8: 21 | D8: 170 | E8: =C8/Constants!$B$27/Constants!$B$28 -> 5.1182062 | F8: =D8/Constants!$B$27/Constants!$B$28 -> 41.433098 | G8: =(F8-32)*Constants!$B$29 -> 5.2400858 | H8: =ABS(E8-G8) -> 0.1218796 | I8: =IF(AND(E8>=Constants!$B$8,E8<=Constants!$B$9,G8>=Constants!$B$8,G8<=Constants!$B$9),IF(H8>Constants!$B$10,"YES","no"),"n/a (out of range)") -> no | J8: 5.18 | K8: 12 | L8: 5.18 | M8: 12 | N8: =IF(M8=Constants!$B$12,"Sensor divergence",IF(M8=Constants!$B$11,"Out of range","Valid")) -> Valid | O8: =IF(AND(K8=Constants!$B$13,M8<0),"Both error",IF(K8=M8,"Identical",IF(AND(K8=Constants!$B$13,M8>=0),"Fixed in v1.0.0",IF(M8=Constants!$B$12,"New: divergence detected","Different")))) -> Identical | P8: =IF(M8<0,"Holds last good PWM, D4 ON","OCR1A = "&M8&" ("&TEXT(M8/Constants!$B$5,"0.0%")&")") -> OCR1A = 12 (04%)
A9: 5 | B9: Upper valid edge (~49.9 °C) | C9: 205 | D9: 500 | E9: =C9/Constants!$B$27/Constants!$B$28 -> 49.963441 | F9: =D9/Constants!$B$27/Constants!$B$28 -> 121.86205 | G9: =(F9-32)*Constants!$B$29 -> 49.91837 | H9: =ABS(E9-G9) -> 0.045071411 | I9: =IF(AND(E9>=Constants!$B$8,E9<=Constants!$B$9,G9>=Constants!$B$8,G9<=Constants!$B$9),IF(H9>Constants!$B$10,"YES","no"),"n/a (out of range)") -> no | J9: 49.94 | K9: 320 | L9: 49.94 | M9: 320 | N9: =IF(M9=Constants!$B$12,"Sensor divergence",IF(M9=Constants!$B$11,"Out of range","Valid")) -> Valid | O9: =IF(AND(K9=Constants!$B$13,M9<0),"Both error",IF(K9=M9,"Identical",IF(AND(K9=Constants!$B$13,M9>=0),"Fixed in v1.0.0",IF(M9=Constants!$B$12,"New: divergence detected","Different")))) -> Identical | P9: =IF(M9<0,"Holds last good PWM, D4 ON","OCR1A = "&M9&" ("&TEXT(M9/Constants!$B$5,"0.0%")&")") -> OCR1A = 320 (100%)
A10: 6 | B10: Old dead zone (~26.5 °C) | C10: 109 | D10: 327 | E10: =C10/Constants!$B$27/Constants!$B$28 -> 26.565927 | F10: =D10/Constants!$B$27/Constants!$B$28 -> 79.697782 | G10: =(F10-32)*Constants!$B$29 -> 26.496118 | H10: =ABS(E10-G10) -> 0.069809408 | I10: =IF(AND(E10>=Constants!$B$8,E10<=Constants!$B$9,G10>=Constants!$B$8,G10<=Constants!$B$9),IF(H10>Constants!$B$10,"YES","no"),"n/a (out of range)") -> no | J10: 26.53 | K10: 15797 | L10: 26.53 | M10: 159 | N10: =IF(M10=Constants!$B$12,"Sensor divergence",IF(M10=Constants!$B$11,"Out of range","Valid")) -> Valid | O10: =IF(AND(K10=Constants!$B$13,M10<0),"Both error",IF(K10=M10,"Identical",IF(AND(K10=Constants!$B$13,M10>=0),"Fixed in v1.0.0",IF(M10=Constants!$B$12,"New: divergence detected","Different")))) -> Fixed in v1.0.0 | P10: =IF(M10<0,"Holds last good PWM, D4 ON","OCR1A = "&M10&" ("&TEXT(M10/Constants!$B$5,"0.0%")&")") -> OCR1A = 159 (50%)
A11: 7 | B11: Below range (~3.9 °C) | C11: 16 | D11: 160 | E11: =C11/Constants!$B$27/Constants!$B$28 -> 3.8995857 | F11: =D11/Constants!$B$27/Constants!$B$28 -> 38.995857 | G11: =(F11-32)*Constants!$B$29 -> 3.8861984 | H11: =ABS(E11-G11) -> 0.013387278 | I11: =IF(AND(E11>=Constants!$B$8,E11<=Constants!$B$9,G11>=Constants!$B$8,G11<=Constants!$B$9),IF(H11>Constants!$B$10,"YES","no"),"n/a (out of range)") -> n/a (out of range) | J11: -99.14 | K11: 15797 | L11: -99 | M11: -1 | N11: =IF(M11=Constants!$B$12,"Sensor divergence",IF(M11=Constants!$B$11,"Out of range","Valid")) -> Out of range | O11: =IF(AND(K11=Constants!$B$13,M11<0),"Both error",IF(K11=M11,"Identical",IF(AND(K11=Constants!$B$13,M11>=0),"Fixed in v1.0.0",IF(M11=Constants!$B$12,"New: divergence detected","Different")))) -> Both error | P11: =IF(M11<0,"Holds last good PWM, D4 ON","OCR1A = "&M11&" ("&TEXT(M11/Constants!$B$5,"0.0%")&")") -> Holds last good PWM, D4 ON
A12: 8 | B12: Above range (~51 °C) | C12: 210 | D12: 509 | E12: =C12/Constants!$B$27/Constants!$B$28 -> 51.182062 | F12: =D12/Constants!$B$27/Constants!$B$28 -> 124.05557 | G12: =(F12-32)*Constants!$B$29 -> 51.136869 | H12: =ABS(E12-G12) -> 0.045193273 | I12: =IF(AND(E12>=Constants!$B$8,E12<=Constants!$B$9,G12>=Constants!$B$8,G12<=Constants!$B$9),IF(H12>Constants!$B$10,"YES","no"),"n/a (out of range)") -> n/a (out of range) | J12: -99.14 | K12: 15797 | L12: -99 | M12: -1 | N12: =IF(M12=Constants!$B$12,"Sensor divergence",IF(M12=Constants!$B$11,"Out of range","Valid")) -> Out of range | O12: =IF(AND(K12=Constants!$B$13,M12<0),"Both error",IF(K12=M12,"Identical",IF(AND(K12=Constants!$B$13,M12>=0),"Fixed in v1.0.0",IF(M12=Constants!$B$12,"New: divergence detected","Different")))) -> Both error | P12: =IF(M12<0,"Holds last good PWM, D4 ON","OCR1A = "&M12&" ("&TEXT(M12/Constants!$B$5,"0.0%")&")") -> Holds last good PWM, D4 ON
A13: 9 | B13: LM35 slightly below range, LM34 valid | C13: 20 | D13: 172 | E13: =C13/Constants!$B$27/Constants!$B$28 -> 4.8744821 | F13: =D13/Constants!$B$27/Constants!$B$28 -> 41.920546 | G13: =(F13-32)*Constants!$B$29 -> 5.5108633 | H13: =ABS(E13-G13) -> 0.63638118 | I13: =IF(AND(E13>=Constants!$B$8,E13<=Constants!$B$9,G13>=Constants!$B$8,G13<=Constants!$B$9),IF(H13>Constants!$B$10,"YES","no"),"n/a (out of range)") -> n/a (out of range) | J13: -99.14 | K13: 15797 | L13: -99 | M13: -1 | N13: =IF(M13=Constants!$B$12,"Sensor divergence",IF(M13=Constants!$B$11,"Out of range","Valid")) -> Out of range | O13: =IF(AND(K13=Constants!$B$13,M13<0),"Both error",IF(K13=M13,"Identical",IF(AND(K13=Constants!$B$13,M13>=0),"Fixed in v1.0.0",IF(M13=Constants!$B$12,"New: divergence detected","Different")))) -> Both error | P13: =IF(M13<0,"Holds last good PWM, D4 ON","OCR1A = "&M13&" ("&TEXT(M13/Constants!$B$5,"0.0%")&")") -> Holds last good PWM, D4 ON
A14: 10 | B14: Divergence just under limit (~4.97 °C apart) | C14: 123 | D14: 316 | E14: =C14/Constants!$B$27/Constants!$B$28 -> 29.978065 | F14: =D14/Constants!$B$27/Constants!$B$28 -> 77.016817 | G14: =(F14-32)*Constants!$B$29 -> 25.006842 | H14: =ABS(E14-G14) -> 4.971223 | I14: =IF(AND(E14>=Constants!$B$8,E14<=Constants!$B$9,G14>=Constants!$B$8,G14<=Constants!$B$9),IF(H14>Constants!$B$10,"YES","no"),"n/a (out of range)") -> no | J14: 27.49 | K14: 166 | L14: 27.49 | M14: 166 | N14: =IF(M14=Constants!$B$12,"Sensor divergence",IF(M14=Constants!$B$11,"Out of range","Valid")) -> Valid | O14: =IF(AND(K14=Constants!$B$13,M14<0),"Both error",IF(K14=M14,"Identical",IF(AND(K14=Constants!$B$13,M14>=0),"Fixed in v1.0.0",IF(M14=Constants!$B$12,"New: divergence detected","Different")))) -> Identical | P14: =IF(M14<0,"Holds last good PWM, D4 ON","OCR1A = "&M14&" ("&TEXT(M14/Constants!$B$5,"0.0%")&")") -> OCR1A = 166 (52%)
A15: 11 | B15: Divergence just over limit (~5.11 °C apart) | C15: 123 | D15: 315 | E15: =C15/Constants!$B$27/Constants!$B$28 -> 29.978065 | F15: =D15/Constants!$B$27/Constants!$B$28 -> 76.773093 | G15: =(F15-32)*Constants!$B$29 -> 24.871453 | H15: =ABS(E15-G15) -> 5.1066117 | I15: =IF(AND(E15>=Constants!$B$8,E15<=Constants!$B$9,G15>=Constants!$B$8,G15<=Constants!$B$9),IF(H15>Constants!$B$10,"YES","no"),"n/a (out of range)") -> YES | J15: 27.42 | K15: 166 | L15: -97 | M15: -2 | N15: =IF(M15=Constants!$B$12,"Sensor divergence",IF(M15=Constants!$B$11,"Out of range","Valid")) -> Sensor divergence | O15: =IF(AND(K15=Constants!$B$13,M15<0),"Both error",IF(K15=M15,"Identical",IF(AND(K15=Constants!$B$13,M15>=0),"Fixed in v1.0.0",IF(M15=Constants!$B$12,"New: divergence detected","Different")))) -> New: divergence detected | P15: =IF(M15<0,"Holds last good PWM, D4 ON","OCR1A = "&M15&" ("&TEXT(M15/Constants!$B$5,"0.0%")&")") -> Holds last good PWM, D4 ON
A16: 12 | B16: Large divergence (30 °C vs 40 °C) | C16: 123 | D16: 427 | E16: =C16/Constants!$B$27/Constants!$B$28 -> 29.978065 | F16: =D16/Constants!$B$27/Constants!$B$28 -> 104.07019 | G16: =(F16-32)*Constants!$B$29 -> 40.034992 | H16: =ABS(E16-G16) -> 10.056927 | I16: =IF(AND(E16>=Constants!$B$8,E16<=Constants!$B$9,G16>=Constants!$B$8,G16<=Constants!$B$9),IF(H16>Constants!$B$10,"YES","no"),"n/a (out of range)") -> YES | J16: 35.01 | K16: 222 | L16: -97 | M16: -2 | N16: =IF(M16=Constants!$B$12,"Sensor divergence",IF(M16=Constants!$B$11,"Out of range","Valid")) -> Sensor divergence | O16: =IF(AND(K16=Constants!$B$13,M16<0),"Both error",IF(K16=M16,"Identical",IF(AND(K16=Constants!$B$13,M16>=0),"Fixed in v1.0.0",IF(M16=Constants!$B$12,"New: divergence detected","Different")))) -> New: divergence detected | P16: =IF(M16<0,"Holds last good PWM, D4 ON","OCR1A = "&M16&" ("&TEXT(M16/Constants!$B$5,"0.0%")&")") -> Holds last good PWM, D4 ON
... A21: 17 | B21: LM34 shorted to AREF (ADC 1023) | C21: 123 | D21: 1023 | E21: =C21/Constants!$B$27/Constants!$B$28 -> 29.978065 | F21: =D21/Constants!$B$27/Constants!$B$28 -> 249.32976 | G21: =(F21-32)*Constants!$B$29 -> 120.72668 | H21: =ABS(E21-G21) -> 90.748616 | I21: =IF(AND(E21>=Constants!$B$8,E21<=Constants!$B$9,G21>=Constants!$B$8,G21<=Constants!$B$9),IF(H21>Constants!$B$10,"YES","no"),"n/a (out of range)") -> n/a (out of range) | J21: -99.14 | K21: 15797 | L21: -99 | M21: -1 | N21: =IF(M21=Constants!$B$12,"Sensor divergence",IF(M21=Constants!$B$11,"Out of range","Valid")) -> Out of range | O21: =IF(AND(K21=Constants!$B$13,M21<0),"Both error",IF(K21=M21,"Identical",IF(AND(K21=Constants!$B$13,M21>=0),"Fixed in v1.0.0",IF(M21=Constants!$B$12,"New: divergence detected","Different")))) -> Both error | P21: =IF(M21<0,"Holds last good PWM, D4 ON","OCR1A = "&M21&" ("&TEXT(M21/Constants!$B$5,"0.0%")&")") -> Holds last good PWM, D4 ON

Sheet LED_Alarm_Matrix
A1: LED and buzzer outputs for every combination of fan test × temperature × fan rotation
A2: Full firmware run: setup() with the fan test, then loop() cycles leading to the condition. Values are the outputs after the last cycle. D6 = fan status LED, D4 = board status LED.
A4: # | B4: Fan startup test | C4: Temperature condition | D4: Fan rotation (last 5 s) | E4: v1.0.0 PWM code | F4: v1.0.0 OCR1A | G4: v1.0.0 D6 fan LED | H4: v1.0.0 D4 board LED | I4: v1.0.0 buzzer | J4: v0.2.1 PWM | K4: v0.2.1 OCR1A | L4: v0.2.1 D6 | M4: v0.2.1 D4 | N4: v0.2.1 buzzer | O4: LEDs/buzzer vs v0.2.1 | P4: Explanation (v1.0.0)
A5: 1 | B5: PASSED | C5: Normal 30 °C | D5: Spinning | E5: 180 | F5: 180 | G5: OFF | H5: OFF | I5: OFF | J5: 180 | K5: 180 | L5: OFF | M5: OFF | N5: OFF | O5: =IF(AND(G5=L5,H5=M5,I5=N5),"Same","Changed: "&IF(G5<>L5,"D6 ","")&IF(H5<>M5,"D4 ","")&IF(I5<>N5,"buzzer","")) -> Same | P5: D6: off. D4: off. Buzzer: off.
A6: 2 | B6: PASSED | C6: Normal 30 °C | D6: Stopped (0 pulses) | E6: 180 | F6: 180 | G6: ON | H6: OFF | I6: ON | J6: 180 | K6: 180 | L6: ON | M6: OFF | N6: ON | O6: =IF(AND(G6=L6,H6=M6,I6=N6),"Same","Changed: "&IF(G6<>L6,"D6 ","")&IF(H6<>M6,"D4 ","")&IF(I6<>N6,"buzzer","")) -> Same | P6: D6: fan stopped. D4: off. Buzzer: fan stopped.
A7: 3 | B7: PASSED | C7: Max temp – 1st cycle at PWM 320 (49.8 °C) | D7: Spinning | E7: 320 | F7: 320 | G7: OFF | H7: OFF | I7: OFF | J7: 320 | K7: 320 | L7: OFF | M7: OFF | N7: OFF | O7: =IF(AND(G7=L7,H7=M7,I7=N7),"Same","Changed: "&IF(G7<>L7,"D6 ","")&IF(H7<>M7,"D4 ","")&IF(I7<>N7,"buzzer","")) -> Same | P7: D6: off. D4: off. Buzzer: off.
A8: 4 | B8: PASSED | C8: Max temp – 1st cycle at PWM 320 (49.8 °C) | D8: Stopped (0 pulses) | E8: 320 | F8: 320 | G8: ON | H8: OFF | I8: ON | J8: 320 | K8: 320 | L8: ON | M8: OFF | N8: ON | O8: =IF(AND(G8=L8,H8=M8,I8=N8),"Same","Changed: "&IF(G8<>L8,"D6 ","")&IF(H8<>M8,"D4 ","")&IF(I8<>N8,"buzzer","")) -> Same | P8: D6: fan stopped. D4: off. Buzzer: fan stopped.
A9: 5 | B9: PASSED | C9: Max temp – 2nd consecutive cycle (sustained) | D9: Spinning | E9: 320 | F9: 320 | G9: OFF | H9: ON | I9: ON | J9: 320 | K9: 320 | L9: OFF | M9: OFF | N9: OFF | O9: =IF(AND(G9=L9,H9=M9,I9=N9),"Same","Changed: "&IF(G9<>L9,"D6 ","")&IF(H9<>M9,"D4 ","")&IF(I9<>N9,"buzzer","")) -> Changed: D4 buzzer | P9: D6: off. D4: sustained max PWM. Buzzer: sustained max PWM.
A10: 6 | B10: PASSED | C10: Max temp – 2nd consecutive cycle (sustained) | D10: Stopped (0 pulses) | E10: 320 | F10: 320 | G10: ON | H10: ON | I10: ON | J10: 320 | K10: 320 | L10: ON | M10: OFF | N10: ON | O10: =IF(AND(G10=L10,H10=M10,I10=N10),"Same","Changed: "&IF(G10<>L10,"D6 ","")&IF(H10<>M10,"D4 ","")&IF(I10<>N10,"buzzer","")) -> Changed: D4 | P10: D6: fan stopped. D4: sustained max PWM. Buzzer: fan stopped, sustained max PWM.
A11: 7 | B11: PASSED | C11: Above 50 °C after sustained max | D11: Spinning | E11: -1 | F11: 320 | G11: OFF | H11: ON | I11: ON | J11: 15797 | K11: 320 | L11: OFF | M11: ON | N11: OFF | O11: =IF(AND(G11=L11,H11=M11,I11=N11),"Same","Changed: "&IF(G11<>L11,"D6 ","")&IF(H11<>M11,"D4 ","")&IF(I11<>N11,"buzzer","")) -> Changed: buzzer | P11: D6: off. D4: temperature out of range, sustained max PWM. Buzzer: sustained max PWM. Fan holds last good PWM (320).
A12: 8 | B12: PASSED | C12: Above 50 °C after sustained max | D12: Stopped (0 pulses) | E12: -1 | F12: 320 | G12: ON | H12: ON | I12: ON | J12: 15797 | K12: 320 | L12: ON | M12: ON | N12: ON | O12: =IF(AND(G12=L12,H12=M12,I12=N12),"Same","Changed: "&IF(G12<>L12,"D6 ","")&IF(H12<>M12,"D4 ","")&IF(I12<>N12,"buzzer","")) -> Same | P12: D6: fan stopped. D4: temperature out of range, sustained max PWM. Buzzer: fan stopped, sustained max PWM. Fan holds last good PWM (320).
A13: 9 | B13: PASSED | C13: Above 50 °C reached directly from 45 °C | D13: Spinning | E13: -1 | F13: 292 | G13: OFF | H13: ON | I13: OFF | J13: 15797 | K13: 292 | L13: OFF | M13: ON | N13: OFF | O13: =IF(AND(G13=L13,H13=M13,I13=N13),"Same","Changed: "&IF(G13<>L13,"D6 ","")&IF(H13<>M13,"D4 ","")&IF(I13<>N13,"buzzer","")) -> Same | P13: D6: off. D4: temperature out of range. Buzzer: off. Fan holds last good PWM (292). Known limitation: max-PWM counter never started, so no buzzer unless the fan stops.
A14: 10 | B14: PASSED | C14: Above 50 °C reached directly from 45 °C | D14: Stopped (0 pulses) | E14: -1 | F14: 292 | G14: ON | H14: ON | I14: ON | J14: 15797 | K14: 292 | L14: ON | M14: ON | N14: ON | O14: =IF(AND(G14=L14,H14=M14,I14=N14),"Same","Changed: "&IF(G14<>L14,"D6 ","")&IF(H14<>M14,"D4 ","")&IF(I14<>N14,"buzzer","")) -> Same | P14: D6: fan stopped. D4: temperature out of range. Buzzer: fan stopped. Fan holds last good PWM (292). Known limitation: max-PWM counter never started, so no buzzer unless the fan stops.
A15: 11 | B15: PASSED | C15: Sensor unplugged (out of range) | D15: Spinning | E15: -1 | F15: 180 | G15: OFF | H15: ON | I15: OFF | J15: 15797 | K15: 180 | L15: OFF | M15: ON | N15: OFF | O15: =IF(AND(G15=L15,H15=M15,I15=N15),"Same","Changed: "&IF(G15<>L15,"D6 ","")&IF(H15<>M15,"D4 ","")&IF(I15<>N15,"buzzer","")) -> Same | P15: D6: off. D4: temperature out of range. Buzzer: off. Fan holds last good PWM (180).
A16: 12 | B16: PASSED | C16: Sensor unplugged (out of range) | D16: Stopped (0 pulses) | E16: -1 | F16: 180 | G16: ON | H16: ON | I16: ON | J16: 15797 | K16: 180 | L16: ON | M16: ON | N16: ON | O16: =IF(AND(G16=L16,H16=M16,I16=N16),"Same","Changed: "&IF(G16<>L16,"D6 ","")&IF(H16<>M16,"D4 ","")&IF(I16<>N16,"buzzer","")) -> Same | P16: D6: fan stopped. D4: temperature out of range. Buzzer: fan stopped. Fan holds last good PWM (180).
... A32: 28 | B32: NOT PASSED | C32: Sensor divergence (30 vs 40 °C) | D32: Stopped (0 pulses) | E32: -2 | F32: 180 | G32: ON | H32: ON | I32: ON | J32: 222 | K32: 222 | L32: ON | M32: ON | N32: ON | O32: =IF(AND(G32=L32,H32=M32,I32=N32),"Same","Changed: "&IF(G32<>L32,"D6 ","")&IF(H32<>M32,"D4 ","")&IF(I32<>N32,"buzzer","")) -> Same | P32: D6: fan test failed, fan stopped. D4: sensor divergence. Buzzer: fan stopped. Fan holds last good PWM (180).

Sheet Sequences
A1: Time sequences (full firmware, cycle by cycle)
A2: Each sequence starts with setup() (fan test PASSED) followed by loop() cycles. Elapsed time uses v1.0.0 timing: loop delay + alarm duration when the buzzer sounded in the previous cycle.
A4: Seq | B4: Scenario | C4: Step | D4: Elapsed s | E4: Input condition | F4: FG pulses (last 5 s) | G4: LM35 °C | H4: LM34 °F | I4: v1.0.0 avg / sentinel | J4: v1.0.0 PWM code | K4: v1.0.0 OCR1A | L4: v1.0.0 max-PWM counter | M4: v1.0.0 D4 | N4: v1.0.0 D6 | O4: v1.0.0 buzzer | P4: v0.2.1 PWM | Q4: v0.2.1 OCR1A | R4: v0.2.1 D4 | S4: v0.2.1 D6 | T4: v0.2.1 buzzer | U4: What happens (v1.0.0)
A5: Sequence A – Normal heat-up and cool-down
A6: A | B6: Normal heat-up and cool-down | C6: 1 | D6: 0 | E6: 25.0 °C | F6: 400 | G6: 25.1 | H6: 77.02 | I6: 25.06 | J6: 152 | K6: 152 | L6: 0 | M6: OFF | N6: OFF | O6: OFF | P6: 152 | Q6: 152 | R6: OFF | S6: OFF | T6: OFF | U6: Normal regulation
A7: A | B7: Normal heat-up and cool-down | C7: 2 | D7: =D6+Constants!$B$21/1000+IF(O6="ON",(2*Constants!$B$22+Constants!$B$23)/1000,0) -> 5 | E7: 35.0 °C | F7: 400 | G7: 35.1 | H7: 95.05 | I7: 35.06 | J7: 222 | K7: 222 | L7: 0 | M7: OFF | N7: OFF | O7: OFF | P7: 222 | Q7: 222 | R7: OFF | S7: OFF | T7: OFF | U7: Normal regulation
A8: A | B8: Normal heat-up and cool-down | C8: 3 | D8: =D7+Constants!$B$21/1000+IF(O7="ON",(2*Constants!$B$22+Constants!$B$23)/1000,0) -> 10 | E8: 45.0 °C | F8: 400 | G8: 45.09 | H8: 113.09 | I8: 45.07 | J8: 292 | K8: 292 | L8: 0 | M8: OFF | N8: OFF | O8: OFF | P8: 292 | Q8: 292 | R8: OFF | S8: OFF | T8: OFF | U8: Normal regulation
A9: A | B9: Normal heat-up and cool-down | C9: 4 | D9: =D8+Constants!$B$21/1000+IF(O8="ON",(2*Constants!$B$22+Constants!$B$23)/1000,0) -> 15 | E9: 48.0 °C | F9: 400 | G9: 48.01 | H9: 118.45 | I9: 48.02 | J9: 313 | K9: 313 | L9: 0 | M9: OFF | N9: OFF | O9: OFF | P9: 313 | Q9: 313 | R9: OFF | S9: OFF | T9: OFF | U9: Normal regulation
A10: A | B10: Normal heat-up and cool-down | C10: 5 | D10: =D9+Constants!$B$21/1000+IF(O9="ON",(2*Constants!$B$22+Constants!$B$23)/1000,0) -> 20 | E10: 49.2 °C | F10: 400 | G10: 49.23 | H10: 120.64 | I10: 49.24 | J10: 320 | K10: 320 | L10: 1 | M10: OFF | N10: OFF | O10: OFF | P10: 320 | Q10: 320 | R10: OFF | S10: OFF | T10: OFF | U10: 1st cycle at PWM 320 → counter = 1, no alarm yet
A11: A | B11: Normal heat-up and cool-down | C11: 6 | D11: =D10+Constants!$B$21/1000+IF(O10="ON",(2*Constants!$B$22+Constants!$B$23)/1000,0) -> 25 | E11: 49.8 °C | F11: 400 | G11: 49.72 | H11: 121.62 | I11: 49.75 | J11: 320 | K11: 320 | L11: 2 | M11: ON | N11: OFF | O11: ON | P11: 320 | Q11: 320 | R11: OFF | S11: OFF | T11: OFF | U11: 2nd consecutive cycle at PWM 320 → sustained max: D4 ON + buzzer
A12: A | B12: Normal heat-up and cool-down | C12: 7 | D12: =D11+Constants!$B$21/1000+IF(O11="ON",(2*Constants!$B$22+Constants!$B$23)/1000,0) -> 31.05 | E12: 49.8 °C | F12: 400 | G12: 49.72 | H12: 121.62 | I12: 49.75 | J12: 320 | K12: 320 | L12: 2 | M12: ON | N12: OFF | O12: ON | P12: 320 | Q12: 320 | R12: OFF | S12: OFF | T12: OFF | U12: Still at max PWM → alarm continues
A13: A | B13: Normal heat-up and cool-down | C13: 8 | D13: =D12+Constants!$B$21/1000+IF(O12="ON",(2*Constants!$B$22+Constants!$B$23)/1000,0) -> 37.1 | E13: 48.0 °C | F13: 400 | G13: 48.01 | H13: 118.45 | I13: 48.02 | J13: 313 | K13: 313 | L13: 0 | M13: OFF | N13: OFF | O13: OFF | P13: 313 | Q13: 313 | R13: OFF | S13: OFF | T13: OFF | U13: Valid lower PWM → counter reset, alarm stops
A14: A | B14: Normal heat-up and cool-down | C14: 9 | D14: =D13+Constants!$B$21/1000+IF(O13="ON",(2*Constants!$B$22+Constants!$B$23)/1000,0) -> 42.1 | E14: 40.0 °C | F14: 400 | G14: 39.97 | H14: 104.07 | I14: 40 | J14: 257 | K14: 257 | L14: 0 | M14: OFF | N14: OFF | O14: OFF | P14: 257 | Q14: 257 | R14: OFF | S14: OFF | T14: OFF | U14: Normal regulation
A15: A | B15: Normal heat-up and cool-down | C15: 10 | D15: =D14+Constants!$B$21/1000+IF(O14="ON",(2*Constants!$B$22+Constants!$B$23)/1000,0) -> 47.1 | E15: 30.0 °C | F15: 400 | G15: 29.98 | H15: 86.03 | I15: 30 | J15: 180 | K15: 180 | L15: 0 | M15: OFF | N15: OFF | O15: OFF | P15: 180 | Q15: 180 | R15: OFF | S15: OFF | T15: OFF | U15: Normal regulation
A17: Sequence B – Over-temperature above 50 °C
A18: B | B18: Over-temperature above 50 °C | C18: 1 | D18: 0 | E18: 45.0 °C | F18: 400 | G18: 45.09 | H18: 113.09 | I18: 45.07 | J18: 292 | K18: 292 | L18: 0 | M18: OFF | N18: OFF | O18: OFF | P18: 292 | Q18: 292 | R18: OFF | S18: OFF | T18: OFF | U18: Normal regulation
A19: B | B19: Over-temperature above 50 °C | C19: 2 | D19: =D18+Constants!$B$21/1000+IF(O18="ON",(2*Constants!$B$22+Constants!$B$23)/1000,0) -> 5 | E19: 49.8 °C | F19: 400 | G19: 49.72 | H19: 121.62 | I19: 49.75 | J19: 320 | K19: 320 | L19: 1 | M19: OFF | N19: OFF | O19: OFF | P19: 320 | Q19: 320 | R19: OFF | S19: OFF | T19: OFF | U19: 1st cycle at PWM 320 → counter = 1, no alarm yet
A20: B | B20: Over-temperature above 50 °C | C20: 3 | D20: =D19+Constants!$B$21/1000+IF(O19="ON",(2*Constants!$B$22+Constants!$B$23)/1000,0) -> 10 | E20: 49.8 °C | F20: 400 | G20: 49.72 | H20: 121.62 | I20: 49.75 | J20: 320 | K20: 320 | L20: 2 | M20: ON | N20: OFF | O20: ON | P20: 320 | Q20: 320 | R20: OFF | S20: OFF | T20: OFF | U20: 2nd consecutive cycle at PWM 320 → sustained max: D4 ON + buzzer
A21: B | B21: Over-temperature above 50 °C | C21: 4 | D21: =D20+Constants!$B$21/1000+IF(O20="ON",(2*Constants!$B$22+Constants!$B$23)/1000,0) -> 16.05 | E21: 51.0 °C | F21: 400 | G21: 50.94 | H21: 123.81 | I21: -99 | J21: -1 | K21: 320 | L21: 2 | M21: ON | N21: OFF | O21: ON | P21: 15797 | Q21: 320 | R21: ON | S21: OFF | T21: OFF | U21: Out of range does not reset the counter → alarm kept, fan holds 320
A22: B | B22: Over-temperature above 50 °C | C22: 5 | D22: =D21+Constants!$B$21/1000+IF(O21="ON",(2*Constants!$B$22+Constants!$B$23)/1000,0) -> 22.1 | E22: 53.0 °C | F22: 400 | G22: 52.89 | H22: 127.47 | I22: -99 | J22: -1 | K22: 320 | L22: 2 | M22: ON | N22: OFF | O22: ON | P22: 15797 | Q22: 320 | R22: ON | S22: OFF | T22: OFF | U22: Out of range does not reset the counter → alarm kept, fan holds 320
A23: B | B23: Over-temperature above 50 °C | C23: 6 | D23: =D22+Constants!$B$21/1000+IF(O22="ON",(2*Constants!$B$22+Constants!$B$23)/1000,0) -> 28.15 | E23: 55.0 °C | F23: 400 | G23: 55.08 | H23: 130.88 | I23: -99 | J23: -1 | K23: 320 | L23: 2 | M23: ON | N23: OFF | O23: ON | P23: 15797 | Q23: 320 | R23: ON | S23: OFF | T23: OFF | U23: Out of range does not reset the counter → alarm kept, fan holds 320
A24: B | B24: Over-temperature above 50 °C | C24: 7 | D24: =D23+Constants!$B$21/1000+IF(O23="ON",(2*Constants!$B$22+Constants!$B$23)/1000,0) -> 34.2 | E24: 51.0 °C | F24: 400 | G24: 50.94 | H24: 123.81 | I24: -99 | J24: -1 | K24: 320 | L24: 2 | M24: ON | N24: OFF | O24: ON | P24: 15797 | Q24: 320 | R24: ON | S24: OFF | T24: OFF | U24: Out of range does not reset the counter → alarm kept, fan holds 320
A25: B | B25: Over-temperature above 50 °C | C25: 8 | D25: =D24+Constants!$B$21/1000+IF(O24="ON",(2*Constants!$B$22+Constants!$B$23)/1000,0) -> 40.25 | E25: 49.8 °C | F25: 400 | G25: 49.72 | H25: 121.62 | I25: 49.75 | J25: 320 | K25: 320 | L25: 2 | M25: ON | N25: OFF | O25: ON | P25: 320 | Q25: 320 | R25: OFF | S25: OFF | T25: OFF | U25: Still at max PWM → alarm continues
A26: B | B26: Over-temperature above 50 °C | C26: 9 | D26: =D25+Constants!$B$21/1000+IF(O25="ON",(2*Constants!$B$22+Constants!$B$23)/1000,0) -> 46.3 | E26: 48.0 °C | F26: 400 | G26: 48.01 | H26: 118.45 | I26: 48.02 | J26: 313 | K26: 313 | L26: 0 | M26: OFF | N26: OFF | O26: OFF | P26: 313 | Q26: 313 | R26: OFF | S26: OFF | T26: OFF | U26: Valid lower PWM → counter reset, alarm stops
A27: B | B27: Over-temperature above 50 °C | C27: 10 | D27: =D26+Constants!$B$21/1000+IF(O26="ON",(2*Constants!$B$22+Constants!$B$23)/1000,0) -> 51.3 | E27: 45.0 °C | F27: 400 | G27: 45.09 | H27: 113.09 | I27: 45.07 | J27: 292 | K27: 292 | L27: 0 | M27: OFF | N27: OFF | O27: OFF | P27: 292 | Q27: 292 | R27: OFF | S27: OFF | T27: OFF | U27: Normal regulation
A29: Sequence C – Sensor failure while at maximum PWM
A30: C | B30: Sensor failure while at maximum PWM | C30: 1 | D30: 0 | E30: 45.0 °C | F30: 400 | G30: 45.09 | H30: 113.09 | I30: 45.07 | J30: 292 | K30: 292 | L30: 0 | M30: OFF | N30: OFF | O30: OFF | P30: 292 | Q30: 292 | R30: OFF | S30: OFF | T30: OFF | U30: Normal regulation
A31: C | B31: Sensor failure while at maximum PWM | C31: 2 | D31: =D30+Constants!$B$21/1000+IF(O30="ON",(2*Constants!$B$22+Constants!$B$23)/1000,0) -> 5 | E31: 49.8 °C | F31: 400 | G31: 49.72 | H31: 121.62 | I31: 49.75 | J31: 320 | K31: 320 | L31: 1 | M31: OFF | N31: OFF | O31: OFF | P31: 320 | Q31: 320 | R31: OFF | S31: OFF | T31: OFF | U31: 1st cycle at PWM 320 → counter = 1, no alarm yet
A32: C | B32: Sensor failure while at maximum PWM | C32: 3 | D32: =D31+Constants!$B$21/1000+IF(O31="ON",(2*Constants!$B$22+Constants!$B$23)/1000,0) -> 10 | E32: 49.8 °C | F32: 400 | G32: 49.72 | H32: 121.62 | I32: 49.75 | J32: 320 | K32: 320 | L32: 2 | M32: ON | N32: OFF | O32: ON | P32: 320 | Q32: 320 | R32: OFF | S32: OFF | T32: OFF | U32: 2nd consecutive cycle at PWM 320 → sustained max: D4 ON + buzzer
A33: C | B33: Sensor failure while at maximum PWM | C33: 4 | D33: =D32+Constants!$B$21/1000+IF(O32="ON",(2*Constants!$B$22+Constants!$B$23)/1000,0) -> 16.05 | E33: Sensor unplugged (ADC 0 / 0) | F33: 400 | G33: 0 | H33: 0 | I33: -99 | J33: -1 | K33: 320 | L33: 2 | M33: ON | N33: OFF | O33: ON | P33: 15797 | Q33: 320 | R33: ON | S33: OFF | T33: OFF | U33: Out of range does not reset the counter → alarm kept, fan holds 320
A34: C | B34: Sensor failure while at maximum PWM | C34: 5 | D34: =D33+Constants!$B$21/1000+IF(O33="ON",(2*Constants!$B$22+Constants!$B$23)/1000,0) -> 22.1 | E34: Sensor unplugged (ADC 0 / 0) | F34: 400 | G34: 0 | H34: 0 | I34: -99 | J34: -1 | K34: 320 | L34: 2 | M34: ON | N34: OFF | O34: ON | P34: 15797 | Q34: 320 | R34: ON | S34: OFF | T34: OFF | U34: Out of range does not reset the counter → alarm kept, fan holds 320
A35: C | B35: Sensor failure while at maximum PWM | C35: 6 | D35: =D34+Constants!$B$21/1000+IF(O34="ON",(2*Constants!$B$22+Constants!$B$23)/1000,0) -> 28.15 | E35: 48.0 °C | F35: 400 | G35: 48.01 | H35: 118.45 | I35: 48.02 | J35: 313 | K35: 313 | L35: 0 | M35: OFF | N35: OFF | O35: OFF | P35: 313 | Q35: 313 | R35: OFF | S35: OFF | T35: OFF | U35: Valid lower PWM → counter reset, alarm stops
A37: Sequence D – Sensor failure during normal operation
A38: D | B38: Sensor failure during normal operation | C38: 1 | D38: 0 | E38: 30.0 °C | F38: 400 | G38: 29.98 | H38: 86.03 | I38: 30 | J38: 180 | K38: 180 | L38: 0 | M38: OFF | N38: OFF | O38: OFF | P38: 180 | Q38: 180 | R38: OFF | S38: OFF | T38: OFF | U38: Normal regulation
A39: D | B39: Sensor failure during normal operation | C39: 2 | D39: =D38+Constants!$B$21/1000+IF(O38="ON",(2*Constants!$B$22+Constants!$B$23)/1000,0) -> 5 | E39: Sensor unplugged (ADC 0 / 0) | F39: 400 | G39: 0 | H39: 0 | I39: -99 | J39: -1 | K39: 180 | L39: 0 | M39: ON | N39: OFF | O39: OFF | P39: 15797 | Q39: 180 | R39: ON | S39: OFF | T39: OFF | U39: Out of range → D4 ON, fan holds last PWM 180
A40: D | B40: Sensor failure during normal operation | C40: 3 | D40: =D39+Constants!$B$21/1000+IF(O39="ON",(2*Constants!$B$22+Constants!$B$23)/1000,0) -> 10 | E40: Sensor unplugged (ADC 0 / 0) | F40: 400 | G40: 0 | H40: 0 | I40: -99 | J40: -1 | K40: 180 | L40: 0 | M40: ON | N40: OFF | O40: OFF | P40: 15797 | Q40: 180 | R40: ON | S40: OFF | T40: OFF | U40: Out of range → D4 ON, fan holds last PWM 180
A41: D | B41: Sensor failure during normal operation | C41: 4 | D41: =D40+Constants!$B$21/1000+IF(O40="ON",(2*Constants!$B$22+Constants!$B$23)/1000,0) -> 15 | E41: 30.0 °C | F41: 400 | G41: 29.98 | H41: 86.03 | I41: 30 | J41: 180 | K41: 180 | L41: 0 | M41: OFF | N41: OFF | O41: OFF | P41: 180 | Q41: 180 | R41: OFF | S41: OFF | T41: OFF | U41: Normal regulation
A43: Sequence E – Fast jump above 50 °C (known limitation)
A44: E | B44: Fast jump above 50 °C (known limitation) | C44: 1 | D44: 0 | E44: 45.0 °C | F44: 400 | G44: 45.09 | H44: 113.09 | I44: 45.07 | J44: 292 | K44: 292 | L44: 0 | M44: OFF | N44: OFF | O44: OFF | P44: 292 | Q44: 292 | R44: OFF | S44: OFF | T44: OFF | U44: Normal regulation
A45: E | B45: Fast jump above 50 °C (known limitation) | C45: 2 | D45: =D44+Constants!$B$21/1000+IF(O44="ON",(2*Constants!$B$22+Constants!$B$23)/1000,0) -> 5 | E45: 52.0 °C | F45: 400 | G45: 51.91 | H45: 125.52 | I45: -99 | J45: -1 | K45: 292 | L45: 0 | M45: ON | N45: OFF | O45: OFF | P45: 15797 | Q45: 292 | R45: ON | S45: OFF | T45: OFF | U45: Out of range → D4 ON, fan holds last PWM 292; Known limitation: jumped over 49–50 °C band, counter never started → D4 only, no buzzer
...

Sheet Fan_Startup_Test
A1: Fan startup test – FG pulses counted in the 1 s window
A2: Full setup() run with the FG interrupt firing N times during the counting window (fan at FAN_TEST_PWM = 128).
A4: FG pulses in 1 s | B4: Fan RPM (formula) | C4: Expected result (formula) | D4: v1.0.0 result | E4: v0.2.1 result | F4: v1.0.0 vs expected | G4: v1.0.0 vs v0.2.1 | H4: v1.0.0 indication | I4: v0.2.1 indication | J4: v1.0.0 serial debug output | K4: Interpretation
A5: 0 | B5: =A5*Constants!$B$30 -> 0 | C5: =IF(AND(A5>Constants!$B$14,A5<Constants!$B$15),"PASSED","NOT PASSED") -> NOT PASSED | D5: NOT PASSED | E5: NOT PASSED | F5: =IF(D5=C5,"OK","CHECK") -> OK | G5: =IF(D5=E5,"Identical","Different") -> Identical | H5: =IF(D5="PASSED","D6 OFF (unless fan stops)","D6 ON permanently") -> D6 ON permanently | I5: =IF(E5="PASSED","D4 OFF (unless temp error)","D4 ON permanently") -> D4 ON permanently | J5: Detected FGPulses: 0 | Test Result: NOT PASSED | K5: Fan not turning, FG line open, or no PWM/12 V to fan
A6: 10 | B6: =A6*Constants!$B$30 -> 300 | C6: =IF(AND(A6>Constants!$B$14,A6<Constants!$B$15),"PASSED","NOT PASSED") -> NOT PASSED | D6: NOT PASSED | E6: NOT PASSED | F6: =IF(D6=C6,"OK","CHECK") -> OK | G6: =IF(D6=E6,"Identical","Different") -> Identical | H6: =IF(D6="PASSED","D6 OFF (unless fan stops)","D6 ON permanently") -> D6 ON permanently | I6: =IF(E6="PASSED","D4 OFF (unless temp error)","D4 ON permanently") -> D4 ON permanently | J6: Detected FGPulses: 10 | Test Result: NOT PASSED | K6: Fan far too slow – possible stall / bearing fault
A7: 30 | B7: =A7*Constants!$B$30 -> 900 | C7: =IF(AND(A7>Constants!$B$14,A7<Constants!$B$15),"PASSED","NOT PASSED") -> NOT PASSED | D7: NOT PASSED | E7: NOT PASSED | F7: =IF(D7=C7,"OK","CHECK") -> OK | G7: =IF(D7=E7,"Identical","Different") -> Identical | H7: =IF(D7="PASSED","D6 OFF (unless fan stops)","D6 ON permanently") -> D6 ON permanently | I7: =IF(E7="PASSED","D4 OFF (unless temp error)","D4 ON permanently") -> D4 ON permanently | J7: Detected FGPulses: 30 | Test Result: NOT PASSED | K7: Fan too slow
A8: 45 | B8: =A8*Constants!$B$30 -> 1350 | C8: =IF(AND(A8>Constants!$B$14,A8<Constants!$B$15),"PASSED","NOT PASSED") -> NOT PASSED | D8: NOT PASSED | E8: NOT PASSED | F8: =IF(D8=C8,"OK","CHECK") -> OK | G8: =IF(D8=E8,"Identical","Different") -> Identical | H8: =IF(D8="PASSED","D6 OFF (unless fan stops)","D6 ON permanently") -> D6 ON permanently | I8: =IF(E8="PASSED","D4 OFF (unless temp error)","D4 ON permanently") -> D4 ON permanently | J8: Detected FGPulses: 45 | Test Result: NOT PASSED | K8: Fan slower than expected (supply voltage low / fan wear)
A9: 50 | B9: =A9*Constants!$B$30 -> 1500 | C9: =IF(AND(A9>Constants!$B$14,A9<Constants!$B$15),"PASSED","NOT PASSED") -> NOT PASSED | D9: NOT PASSED | E9: NOT PASSED | F9: =IF(D9=C9,"OK","CHECK") -> OK | G9: =IF(D9=E9,"Identical","Different") -> Identical | H9: =IF(D9="PASSED","D6 OFF (unless fan stops)","D6 ON permanently") -> D6 ON permanently | I9: =IF(E9="PASSED","D4 OFF (unless temp error)","D4 ON permanently") -> D4 ON permanently | J9: Detected FGPulses: 50 | Test Result: NOT PASSED | K9: Slightly slow
A10: 52 | B10: =A10*Constants!$B$30 -> 1560 | C10: =IF(AND(A10>Constants!$B$14,A10<Constants!$B$15),"PASSED","NOT PASSED") -> NOT PASSED | D10: NOT PASSED | E10: NOT PASSED | F10: =IF(D10=C10,"OK","CHECK") -> OK | G10: =IF(D10=E10,"Identical","Different") -> Identical | H10: =IF(D10="PASSED","D6 OFF (unless fan stops)","D6 ON permanently") -> D6 ON permanently | I10: =IF(E10="PASSED","D4 OFF (unless temp error)","D4 ON permanently") -> D4 ON permanently | J10: Detected FGPulses: 52 | Test Result: NOT PASSED | K10: Lower boundary – fails (window is 53…56)
A11: 53 | B11: =A11*Constants!$B$30 -> 1590 | C11: =IF(AND(A11>Constants!$B$14,A11<Constants!$B$15),"PASSED","NOT PASSED") -> PASSED | D11: PASSED | E11: PASSED | F11: =IF(D11=C11,"OK","CHECK") -> OK | G11: =IF(D11=E11,"Identical","Different") -> Identical | H11: =IF(D11="PASSED","D6 OFF (unless fan stops)","D6 ON permanently") -> D6 OFF (unless fan stops) | I11: =IF(E11="PASSED","D4 OFF (unless temp error)","D4 ON permanently") -> D4 OFF (unless temp error) | J11: Detected FGPulses: 53 | Test Result: PASSED | K11: Lowest passing value
A12: 54 | B12: =A12*Constants!$B$30 -> 1620 | C12: =IF(AND(A12>Constants!$B$14,A12<Constants!$B$15),"PASSED","NOT PASSED") -> PASSED | D12: PASSED | E12: PASSED | F12: =IF(D12=C12,"OK","CHECK") -> OK | G12: =IF(D12=E12,"Identical","Different") -> Identical | H12: =IF(D12="PASSED","D6 OFF (unless fan stops)","D6 ON permanently") -> D6 OFF (unless fan stops) | I12: =IF(E12="PASSED","D4 OFF (unless temp error)","D4 ON permanently") -> D4 OFF (unless temp error) | J12: Detected FGPulses: 54 | Test Result: PASSED | K12: Healthy fan (typical 53–55)
